Workbook
Name B: '[2]2006상반기'!#REF!
Name B: '[2]2006상반기'!#REF!
Name B: '[2]2006상반기'!#REF!
Name B: '[2]2006상반기'!#REF!
Name B: '[2]2006상반기'!#REF!
Name M: '[2]2006상반기'!#REF!
Name M: '[2]2006상반기'!#REF!
Name M: '[2]2006상반기'!#REF!
Name M: '[2]2006상반기'!#REF!
Name M: '[2]2006상반기'!#REF!
Name 계약단위: [3]Index.!$G$2:$G$4
Name 계약단위: [4]Index.!$G$2:$G$4
Name 고객사: '[2]2006상반기'!#REF!
Name 고객사: '[2]2006상반기'!#REF!
Name 고객사: '[2]2006상반기'!#REF!
Name 고객사: '[2]2006상반기'!#REF!
Name 고객사: '[2]2006상반기'!#REF!
Name 기업분류: '[2]2006상반기'!#REF!
Name 기업분류: '[2]2006상반기'!#REF!
Name 기업분류: '[2]2006상반기'!#REF!
Name 기업분류: '[2]2006상반기'!#REF!
Name 기업분류: '[2]2006상반기'!#REF!
Name 기업순위: '[2]2006상반기'!#REF!
Name 기업순위: '[2]2006상반기'!#REF!
Name 기업순위: '[2]2006상반기'!#REF!
Name 기업순위: '[2]2006상반기'!#REF!
Name 기업순위: '[2]2006상반기'!#REF!
Name 년도: [3]Index.!$E$2:$E$7
Name 년도: [4]Index.!$E$2:$E$7
Name ㅁ: '[2]2006상반기'!#REF!
Name ㅁ: '[2]2006상반기'!#REF!
Name ㅁ: '[2]2006상반기'!#REF!
Name ㅁ: '[2]2006상반기'!#REF!
Name ㅁ: '[2]2006상반기'!#REF!
Name 매출: '[2]2006상반기'!#REF!
Name 매출: '[2]2006상반기'!#REF!
Name 매출: '[2]2006상반기'!#REF!
Name 매출: '[2]2006상반기'!#REF!
Name 매출: '[2]2006상반기'!#REF!
Name 사전영업: [5]Index.!$M$2:$M$12
Name 산업분류: '[2]2006상반기'!#REF!
Name 산업분류: '[2]2006상반기'!#REF!
Name 산업분류: '[2]2006상반기'!#REF!
Name 산업분류: '[2]2006상반기'!#REF!
Name 산업분류: '[2]2006상반기'!#REF!
Name 상품유형: '[6]Index 매출유형신구분'!$D$48:$D$70
Name ㅇㅇ: #REF!
Name ㅇㅇ: #REF!
Name ㅇㅇ: #REF!
Name ㅇㅇ: #REF!
Name ㅇㅇ: #REF!
Name ㅇㅇ: #REF!
Name 영업대표: '[2]2006상반기'!#REF!
Name 영업대표: '[2]2006상반기'!#REF!
Name 영업대표: '[2]2006상반기'!#REF!
Name 영업대표: '[2]2006상반기'!#REF!
Name 영업대표: '[2]2006상반기'!#REF!
Name 월: [3]Index.!$F$2:$F$15
Name 월: [4]Index.!$F$2:$F$15
Name 인아웃: '[2]2006상반기'!#REF!

Sheet 25Pivot
A3: 행 레이블 | B3: 합계 : 6월 예상 | C3: 합계 : 7월 예상 | D3: 합계 : 8월 예상 | E3: 합계 : 9월 예상 | F3: 합계 : 10월 예상 | G3: 합계 : 11월 예상 | H3: 합계 : 12월 예상
A4: 01 확정 | B4: 78100000 | C4: 48800000 | D4: 47800000 | E4: 90300000 | F4: 78800000 | G4: 104100000 | H4: 333800000
A5: 02 가망 | B5: 14000000 | C5: 20000000 | D5: 4000000 | E5: 39000000 | F5: 29000000 | G5: 73000000 | H5: 180000000
A6: 03 기회 | B6: 136000000 | C6: 15000000 | D6: 91000000 | E6: 34000000 | F6: 178000000 | G6: 20000000 | H6: 702000000
A7: 총합계 | B7: 228100000 | C7: 83800000 | D7: 142800000 | E7: 163300000 | F7: 285800000 | G7: 197100000 | H7: 1215800000
B11: 열 레이블
A12: 행 레이블 | B12: 01 확정 | C12: 02 가망 | D12: 03 기회 | E12: 총합계
A13: 최재희
A14: 김성경
A15: 하예진
A16: 최수진
A17: 방유진
A18: 양은희
A19: (비어 있음)
A20: 이유진(퇴사)
A21: 김지훈
A22: 박혜원
A23: 방인혜
A24: 강건모
A25: 이재성
A26: 25년 확정/가망/기회 | B26: (다중 항목)
A28: 행 레이블 | B28: 합계 : 6월 예상 | C28: 합계 : 7월 예상 | D28: 합계 : 8월 예상 | E28: 합계 : 9월 예상 | F28: 합계 : 10월 예상 | G28: 합계 : 11월 예상
A29: 01. 이러닝 - 통합위탁 | B29: 5200000 | C29: 5200000 | D29: 5200000 | E29: 4700000 | F29: 42200000 | G29: 3900000
A30: 02. 이러닝 - 단과 | B30: 170500000 | C30: 29500000 | D30: 32500000 | E30: 84000000 | F30: 33500000 | G30: 53500000
A31: 03. 이러닝 - 법정 | B31: 25400000 | C31: 21100000 | D31: 22100000 | E31: 21600000 | F31: 68100000 | G31: 22700000
A32: 04. 이러닝 - 마이크로러닝
A33: 07. 이러닝 - 컨텐츠 임대/판매 | D33: 50000000
A34: 08. 하이브리드러닝 - 하이브리드형 러닝 | B34: 9000000 | C34: 5000000 | D34: 29000000 | E34: 11000000 | F34: 120000000 | G34: 54000000
A35: 09. 하이브리드러닝 - 순수 오프라인 | B35: 7000000 | C35: 17000000 | D35: 0 | E35: 32000000 | F35: 0 | G35: 7000000
A36: 10. 구독 - 휴넷CEO멤버십
A37: 14. 컨텐츠 - 컨텐츠 개발 | B37: 10000000 | C37: 5000000
A38: 19. 운영 - 운영매출 | B38: 0 | C38: 0 | D38: 0 | E38: 2000000 | F38: 0 | G38: 0
A39: 24. 기타 - 포럼 | D39: 2000000 | E39: 7000000
A40: 25. 기타 - 기타 | D40: 1000000
A41: 26. 이러닝 - 정부지원사업 | B41: 0 | C41: 0 | D41: 0 | E41: 0 | F41: 0 | G41: 55000000
A42: 28.구독 - 휴넷FLEX | B42: 0 | C42: 0 | D42: 0 | E42: 0 | F42: 0 | G42: 0
A43: (비어 있음) | B43: 1000000 | C43: 1000000 | D43: 1000000 | E43: 1000000 | F43: 22000000 | G43: 1000000
A44: 총합계 | B44: 228100000 | C44: 83800000 | D44: 142800000 | E44: 163300000 | F44: 285800000 | G44: 197100000
A118: 행 레이블 | B118: 합계 : 6월 예상 | C118: 합계 : 7월 예상 | D118: 합계 : 8월 예상 | E118: 합계 : 9월 예상 | F118: 합계 : 10월 예상 | G118: 합계 : 11월 예상 | H118: 합계 : 12월 예상
A119: 01 확정 | B119: 78100000 | C119: 48800000 | D119: 47800000 | E119: 90300000 | F119: 78800000 | G119: 104100000 | H119: 333800000
...

Sheet 수주리스트
A2: 월 | B2: 수주일 | C2: 영업대표 | D2: 기업명 | E2: 기업코드 | F2: 사업유형 | G2: 25년 매출 | H2: 26년 매출 | I2: 27년 매출 | J2: 총 수주금액 | K2: 매출발생월 | L2: 비고1(신규/기타) | M2: 비고2(법정표시) | N2: 비고3(쓰고 싶은거 쓰세요) | O2: 인/아웃바운드 | P2: databook 반영시점 (관리자 수정)
A3: 2월 | B3: 45708 | C3: 김두희 | D3: 국립해양생물자원관 | E3: 18624 | F3: 01. 이러닝 - 통합위탁 | G3: 40000000 | J3: =SUM(G3:I3) -> 40000000
A4: 2월 | B4: 45715 | C4: 김두희 | D4: 오비맥주 주식회사 | E4: 1966 | F4: 03. 이러닝 - 법정 | G4: 10000000 | J4: =SUM(G4:I4) -> 10000000
A5: 2월 | B5: 45715 | C5: 이나래 | D5: 대한산업안전협회 | E5: 10651 | F5: 08. 하이브리드러닝 - 하이브리드형 러닝 | G5: 83000000 | J5: =SUM(G5:I5) -> 83000000
A6: 3월 | B6: 45722 | C6: 하예진 | D6: 파마리서치 | E6: 20949 | F6: 08. 하이브리드러닝 - 하이브리드형 러닝 | G6: 85000000 | J6: =SUM(G6:I6) -> 85000000
A7: 3월 | B7: 45729 | J7: =SUM(G7:I7) -> 0
A8: 3월 | B8: 45729 | J8: =SUM(G8:I8) -> 0
A9: 3월 | B9: 45729 | J9: =SUM(G9:I9) -> 0
A10: 3월 | B10: 45729 | J10: =SUM(G10:I10) -> 0
A11: 3월 | B11: 45729 | J11: =SUM(G11:I11) -> 0
A12: 3월 | B12: 45729 | J12: =SUM(G12:I12) -> 0
A13: 3월 | B13: 45729 | J13: =SUM(G13:I13) -> 0
A14: 3월 | B14: 45729 | J14: =SUM(G14:I14) -> 0
A15: 3월 | B15: 45729 | J15: =SUM(G15:I15) -> 0
A16: 3월 | B16: 45729 | J16: =SUM(G16:I16) -> 0
A17: 3월 | B17: 45729 | J17: =SUM(G17:I17) -> 0
A18: 3월 | B18: 45729 | J18: =SUM(G18:I18) -> 0
... A35: 3월 | B35: 45729 | J35: =SUM(G35:I35) -> 0
J36: =SUM(G36:I36) -> 0
J37: =SUM(G37:I37) -> 0
J38: =SUM(G38:I38) -> 0
J39: =SUM(G39:I39) -> 0
J40: =SUM(G40:I40) -> 0

Sheet 20250707
C1: 1 | D1: 2 | E1: 3 | F1: 4 | G1: 5 | H1: 6 | I1: 7 | J1: 8 | K1: 9 | L1: 10 | M1: 11 | N1: 12 | O1: 13 | P1: 14 | Q1: 15 | R1: 16 | S1: 17 | T1: 18 | U1: 19 | V1: 20 | W1: 21 | X1: 22 | Y1: 23 | Z1: 24 | AA1: 25 | AB1: 26 | AC1: 27 | AD1: 28 | AE1: 29 | AF1: 30 | AG1: 31 | AH1: 32 | AI1: 33 | AJ1: 34 | AK1: 35 | AL1: 36 | AM1: 37 | AN1: 38 | AO1: 39 | AP1: 40 | AQ1: 41 | AR1: 42 | AS1: 43
A2: no | B2: 연도 | C2: 영업기회코드 | D2: 담당팀 | E2: 운영대표 | F2: 그룹사명 | G2: 그룹사코드 | H2: 기업명 | I2: 기업코드 | J2: 채널명 | K2: 채널코드 | L2: 서비스시작일 | M2: 서비스종료일 | N2: 사업유형(대) | O2: 사업유형(중) | P2: 멤버십 | Q2: 영업단계 | R2: 등록유무 | S2: 확정예상 | T2: 마감 | U2: 예상마감 | V2: 1월예상 | W2: 1월마감 | X2: 2월예상 | Y2: 2월마감 | Z2: 3월예상 | AA2: 3월마감 | AB2: 4월예상 | AC2: 4월마감 | AD2: 5월예상 | AE2: 5월마감 | AF2: 6월예상 | AG2: 6월마감 | AH2: 7월예상 | AI2: 7월마감 | AJ2: 8월예상 | AK2: 8월마감 | AL2: 9월에상 | AM2: 9월마감 | AN2: 10월예상 | AO2: 10월마감 | AP2: 11월예상 | AQ2: 11월마감 | AR2: 12월에상 | AS2: 12월마감
C3: 디지털아카이브 | Q3: 03 기회
A4: 1 | B4: 2025 | C4: 60871-25-001 | D4: 기업교육4팀 | E4: 최수진 | F4: 뉴트리원 | G4: 19303 | H4: 뉴원풀필먼트 | I4: 60871 | L4: 2025-01-01 00:00:00.0 | M4: 2025-12-31 00:00:00.0 | N4: =VLOOKUP(O4,index!$Q:$R,2,0) -> 01. 이러닝 - 통합위탁 | O4: 통합위탁 | P4: 없음 | Q4: 01 확정 | R4: =VLOOKUP(C4,'26년 databook(취합)'!$M:$M,2,0) -> #N/A | U4: 0
A5: 2 | B5: 2025 | C5: 60870-25-001 | D5: 기업교육4팀 | E5: 최수진 | F5: 뉴트리원 | G5: 19303 | H5: 딥런 | I5: 60870 | L5: 2025-01-01 00:00:00.0 | M5: 2025-12-31 00:00:00.0 | N5: =VLOOKUP(O5,index!$Q:$R,2,0) -> 01. 이러닝 - 통합위탁 | O5: 통합위탁 | P5: 없음 | Q5: 01 확정 | R5: =VLOOKUP(C5,'26년 databook(취합)'!$M:$M,2,0) -> #N/A | U5: 0
A6: 3 | B6: 2025 | C6: 25824-25-001 | D6: 기업교육4팀 | E6: 김두희 | F6: SK온테크플러스 | G6: 25824 | H6: SK온테크플러스 | I6: 25824 | L6: 2025-01-01 00:00:00.0 | M6: 2025-12-31 00:00:00.0 | N6: =VLOOKUP(O6,index!$Q:$R,2,0) -> 03. 이러닝 - 법정 | O6: 법정 | P6: 없음 | Q6: 01 확정 | R6: =VLOOKUP(C6,'26년 databook(취합)'!$M:$M,2,0) -> #N/A | S6: 4356000 | U6: 2178000 | AH6: 2178000 | AR6: 2178000
A7: 4 | B7: 2025 | C7: 63875-25-001 | D7: 기업교육4팀 | E7: 방유진 | F7: E 우선지원기업전용 | G7: 42145 | H7: 무진전설 | I7: 63875 | L7: 2025-01-01 00:00:00.0 | M7: 2025-12-31 00:00:00.0 | N7: =VLOOKUP(O7,index!$Q:$R,2,0) -> 02. 이러닝 - 단과 | O7: 단과 | P7: 없음 | Q7: 01 확정 | R7: =VLOOKUP(C7,'26년 databook(취합)'!$M:$M,2,0) -> #N/A | U7: 0
A8: 5 | B8: 2025 | C8: 63258-25-001 | D8: 기업교육4팀 | E8: 방유진 | F8: E 우선지원기업전용 | G8: 42145 | H8: 한국관세정보원 | I8: 63258 | L8: 2025-01-01 00:00:00.0 | M8: 2025-12-31 00:00:00.0 | N8: =VLOOKUP(O8,index!$Q:$R,2,0) -> 02. 이러닝 - 단과 | O8: 단과 | P8: 없음 | Q8: 01 확정 | R8: =VLOOKUP(C8,'26년 databook(취합)'!$M:$M,2,0) -> #N/A | U8: 0
A9: 6 | B9: 2025 | C9: 61757-25-001 | D9: 기업교육4팀 | E9: 방유진 | F9: E 우선지원기업전용 | G9: 42145 | H9: 조아텍 | I9: 61757 | L9: 2025-01-01 00:00:00.0 | M9: 2025-12-31 00:00:00.0 | N9: =VLOOKUP(O9,index!$Q:$R,2,0) -> 02. 이러닝 - 단과 | O9: 단과 | P9: 없음 | Q9: 01 확정 | R9: =VLOOKUP(C9,'26년 databook(취합)'!$M:$M,2,0) -> #N/A | U9: 0
A10: 7 | B10: 2025 | C10: 48959-25-001 | D10: 기업교육4팀 | E10: 방유진 | F10: G 우선지원기업전용 | G10: 46018 | H10: 브링코 | I10: 48959 | L10: 2025-01-01 00:00:00.0 | M10: 2025-12-31 00:00:00.0 | N10: =VLOOKUP(O10,index!$Q:$R,2,0) -> 02. 이러닝 - 단과 | O10: 단과 | P10: 없음 | Q10: 01 확정 | R10: =VLOOKUP(C10,'26년 databook(취합)'!$M:$M,2,0) -> #N/A | U10: 0
A11: 8 | B11: 2025 | C11: 23567-25-001 | D11: 기업교육4팀 | E11: 방유진 | F11: E 우선지원기업전용 | G11: 42145 | H11: 디에이치오토넥스 | I11: 23567 | J11: 대유플러스 | K11: G00065-C00475 | L11: 2025-01-01 00:00:00.0 | M11: 2025-12-31 00:00:00.0 | N11: =VLOOKUP(O11,index!$Q:$R,2,0) -> 02. 이러닝 - 단과 | O11: 단과 | P11: 없음 | Q11: 01 확정 | R11: =VLOOKUP(C11,'26년 databook(취합)'!$M:$M,2,0) -> #N/A | U11: 0
A12: 9 | B12: 2025 | C12: 63854-25-001 | D12: 기업교육4팀 | E12: 최수진 | F12: 중앙홀딩스_MBA | G12: 43699 | H12: 휘닉스중앙제주 주식회사_MBA | I12: 63854 | L12: 2025-01-01 00:00:00.0 | M12: 2025-12-31 00:00:00.0 | N12: =VLOOKUP(O12,index!$Q:$R,2,0) -> 01. 이러닝 - 통합위탁 | O12: 통합위탁 | P12: 없음 | Q12: 01 확정 | R12: =VLOOKUP(C12,'26년 databook(취합)'!$M:$M,2,0) -> #N/A | U12: 0
A13: 10 | B13: 2025 | C13: 59547-25-001 | D13: 기업교육4팀 | E13: 하예진 | F13: H 우선지원기업전용 | G13: 45802 | H13: 엘씨스퀘어 | I13: 59547 | L13: 2025-01-01 00:00:00.0 | M13: 2025-12-31 00:00:00.0 | N13: =VLOOKUP(O13,index!$Q:$R,2,0) -> 02. 이러닝 - 단과 | O13: 단과 | P13: 없음 | Q13: 01 확정 | R13: =VLOOKUP(C13,'26년 databook(취합)'!$M:$M,2,0) -> #N/A | U13: 0
A14: 11 | B14: 2025 | C14: 63853-25-001 | D14: 기업교육4팀 | E14: 최수진 | F14: 중앙홀딩스_MBA | G14: 43699 | H14: 허스트중앙유한회사_MBA | I14: 63853 | L14: 2025-01-01 00:00:00.0 | M14: 2025-12-31 00:00:00.0 | N14: =VLOOKUP(O14,index!$Q:$R,2,0) -> 01. 이러닝 - 통합위탁 | O14: 통합위탁 | P14: 없음 | Q14: 01 확정 | R14: =VLOOKUP(C14,'26년 databook(취합)'!$M:$M,2,0) -> #N/A | U14: 0
A15: 12 | B15: 2025 | C15: 44973-25-001 | D15: 기업교육4팀 | E15: 하예진 | F15: H 우선지원기업전용 | G15: 45802 | H15: 노블트리 | I15: 44973 | J15: 노블트리 | K15: G02169-C03653 | L15: 2025-01-01 00:00:00.0 | M15: 2025-12-31 00:00:00.0 | N15: =VLOOKUP(O15,index!$Q:$R,2,0) -> 02. 이러닝 - 단과 | O15: 단과 | P15: 없음 | Q15: 01 확정 | R15: =VLOOKUP(C15,'26년 databook(취합)'!$M:$M,2,0) -> #N/A | U15: 0
A16: 13 | B16: 2025 | C16: 19212-25-001 | D16: 기업교육4팀 | E16: 하예진 | F16: H 우선지원기업전용 | G16: 45802 | H16: 팩플러스 | I16: 19212 | L16: 2025-01-01 00:00:00.0 | M16: 2025-12-31 00:00:00.0 | N16: =VLOOKUP(O16,index!$Q:$R,2,0) -> 02. 이러닝 - 단과 | O16: 단과 | P16: 없음 | Q16: 01 확정 | R16: =VLOOKUP(C16,'26년 databook(취합)'!$M:$M,2,0) -> #N/A | U16: 0
A17: 14 | B17: 2025 | C17: 63809-25-001 | D17: 기업교육4팀 | E17: 최수진 | F17: B 우선지원기업전용 | G17: 42108 | H17: 디피월드로지스틱스코리아 | I17: 63809 | L17: 2025-01-01 00:00:00.0 | M17: 2025-12-31 00:00:00.0 | N17: =VLOOKUP(O17,index!$Q:$R,2,0) -> 01. 이러닝 - 통합위탁 | O17: 통합위탁 | P17: 없음 | Q17: 01 확정 | R17: =VLOOKUP(C17,'26년 databook(취합)'!$M:$M,2,0) -> #N/A | U17: 0
A18: 15 | B18: 2025 | C18: 53859-25-001 | D18: 기업교육4팀 | E18: 최수진 | F18: 엠엑스엔커머스코리아 | G18: 53621 | H18: 스페이시스원 | I18: 53859 | L18: 2025-01-01 00:00:00.0 | M18: 2025-12-31 00:00:00.0 | N18: =VLOOKUP(O18,index!$Q:$R,2,0) -> 01. 이러닝 - 통합위탁 | O18: 통합위탁 | P18: 없음 | Q18: 01 확정 | R18: =VLOOKUP(C18,'26년 databook(취합)'!$M:$M,2,0) -> #N/A | U18: 0
A19: 16 | B19: 2025 | C19: 53858-25-001 | D19: 기업교육4팀 | E19: 최수진 | F19: 엠엑스엔커머스코리아 | G19: 53621 | H19: 글로벌쉬핑마스터앤투앤 | I19: 53858 | L19: 2025-01-01 00:00:00.0 | M19: 2025-12-31 00:00:00.0 | N19: =VLOOKUP(O19,index!$Q:$R,2,0) -> 01. 이러닝 - 통합위탁 | O19: 통합위탁 | P19: 없음 | Q19: 01 확정 | R19: =VLOOKUP(C19,'26년 databook(취합)'!$M:$M,2,0) -> #N/A | U19: 0
A20: 17 | B20: 2025 | C20: 28912-25-003 | D20: 기업교육4팀 | E20: 최재희 | F20: 이노배어케이티아이파이어드히터스 | G20: 28912 | H20: 이노배어케이티아이파이어드히터스 | I20: 28912 | J20: 이노배어케이티아이파이어드히터스 | K20: G00726-C01454 | L20: 2025-01-01 00:00:00.0 | M20: 2025-12-31 00:00:00.0 | N20: =VLOOKUP(O20,index!$Q:$R,2,0) -> 01. 이러닝 - 통합위탁 | O20: 통합위탁 | P20: 없음 | Q20: 01 확정 | R20: =VLOOKUP(C20,'26년 databook(취합)'!$M:$M,2,0) -> #N/A | U20: 0
A21: 18 | B21: 2025 | C21: 64460-25-001 | D21: 기업교육4팀 | E21: 방유진 | F21: E 우선지원기업전용 | G21: 42145 | H21: 법무법인 엘리트로 | I21: 64460 | L21: 2025-01-01 00:00:00.0 | M21: 2025-12-31 00:00:00.0 | N21: =VLOOKUP(O21,index!$Q:$R,2,0) -> 02. 이러닝 - 단과 | O21: 단과 | P21: 없음 | Q21: 01 확정 | R21: =VLOOKUP(C21,'26년 databook(취합)'!$M:$M,2,0) -> #N/A | U21: 0
A22: 19 | B22: 2025 | C22: 13557-25-001 | D22: 기업교육4팀 | E22: 방유진 | F22: 한국법령정보원 | G22: 13557 | H22: 한국법령정보원 | I22: 13557 | L22: 2025-01-01 00:00:00.0 | M22: 2025-12-31 00:00:00.0 | N22: =VLOOKUP(O22,index!$Q:$R,2,0) -> 09. 하이브리드러닝 - 순수 오프라인 | O22: 순수 오프라인 | P22: 없음 | Q22: 01 확정 | R22: =VLOOKUP(C22,'26년 databook(취합)'!$M:$M,2,0) -> #N/A | U22: 0
A23: 20 | B23: 2025 | C23: 42905-25-001 | D23: 기업교육4팀 | E23: 최재희 | F23: A 우선지원기업전용 | G23: 28849 | H23: 한국통신사업자연합회 | I23: 42905 | L23: 2025-07-01 00:00:00.0 | M23: 2025-12-31 00:00:00.0 | N23: =VLOOKUP(O23,index!$Q:$R,2,0) -> 02. 이러닝 - 단과 | O23: 단과 | P23: 없음 | Q23: 01 확정 | R23: =VLOOKUP(C23,'26년 databook(취합)'!$M:$M,2,0) -> #N/A | T23: 1350000 | U23: 1350000 | W23: 0 | Y23: 0 | AA23: 0 | AC23: 0 | AE23: 0 | AG23: 0 | AI23: 1350000 | AK23: 0 | AM23: 0 | AO23: 0 | AQ23: 0 | AS23: 0
A24: 21 | B24: 2025 | C24: 64435-25-001 | D24: 기업교육4팀 | E24: 김성경 | F24: 휴넷 HRD 아카이브_25/07/20 | G24: 63746 | H24: 소통을디자인하는사람들_A25 | I24: 64435 | L24: 2025-01-01 00:00:00.0 | M24: 2025-12-31 00:00:00.0 | N24: =VLOOKUP(O24,index!$Q:$R,2,0) -> 26. 이러닝 - 정부지원사업 | O24: 정부지원사업 | P24: 없음 | Q24: 01 확정 | R24: =VLOOKUP(C24,'26년 databook(취합)'!$M:$M,2,0) -> #N/A | S24: 140000 | U24: 126000 | AH24: 14000 | AR24: 126000
A25: 22 | B25: 2025 | C25: 27940-25-001 | D25: 기업교육4팀 | E25: 최수진 | F25: 호식이두마리치킨 | G25: 27938 | H25: 제이유(JU) 유통 | I25: 27940 | J25: 호식이두마리치킨 | K25: G01104-C01833 | L25: 2025-01-01 00:00:00.0 | M25: 2025-12-31 00:00:00.0 | N25: =VLOOKUP(O25,index!$Q:$R,2,0) -> 01. 이러닝 - 통합위탁 | O25: 통합위탁 | P25: 없음 | Q25: 01 확정 | R25: =VLOOKUP(C25,'26년 databook(취합)'!$M:$M,2,0) -> #N/A | T25: 180000 | U25: 180000 | W25: 0 | Y25: 0 | AA25: 0 | AC25: 0 | AE25: 0 | AG25: 0 | AI25: 180000 | AK25: 0 | AM25: 0 | AO25: 0 | AQ25: 0 | AS25: 0
A26: 23 | B26: 2025 | C26: 60945-25-001 | D26: 기업교육4팀 | E26: 최수진 | F26: 호식이두마리치킨 | G26: 27938 | H26: 대성통상 | I26: 60945 | L26: 2025-01-01 00:00:00.0 | M26: 2025-12-31 00:00:00.0 | N26: =VLOOKUP(O26,index!$Q:$R,2,0) -> 01. 이러닝 - 통합위탁 | O26: 통합위탁 | P26: 없음 | Q26: 01 확정 | R26: =VLOOKUP(C26,'26년 databook(취합)'!$M:$M,2,0) -> #N/A | T26: 30000 | U26: 30000 | W26: 0 | Y26: 0 | AA26: 0 | AC26: 0 | AE26: 0 | AG26: 0 | AI26: 30000 | AK26: 0 | AM26: 0 | AO26: 0 | AQ26: 0 | AS26: 0
A27: 24 | B27: 2025 | C27: 61097-25-001 | D27: 기업교육4팀 | E27: 최수진 | F27: 주식회사 미코하이테크 | G27: 61097 | H27: 주식회사 미코하이테크 | I27: 61097 | L27: 2025-01-01 00:00:00.0 | M27: 2025-12-31 00:00:00.0 | N27: =VLOOKUP(O27,index!$Q:$R,2,0) -> 01. 이러닝 - 통합위탁 | O27: 통합위탁 | P27: 없음 | Q27: 01 확정 | R27: =VLOOKUP(C27,'26년 databook(취합)'!$M:$M,2,0) -> #N/A | T27: 1268500 | U27: 1268500 | W27: 0 | Y27: 0 | AA27: 0 | AC27: 0 | AE27: 0 | AG27: 0 | AI27: 1268500 | AK27: 0 | AM27: 0 | AO27: 0 | AQ27: 0 | AS27: 0
A28: 25 | B28: 2025 | C28: 9198-25-001 | D28: 기업교육4팀 | E28: 방유진 | F28: 세양폴리머 | G28: 9198 | H28: 세양폴리머 | I28: 9198 | L28: 2025-01-01 00:00:00.0 | M28: 2025-12-31 00:00:00.0 | N28: =VLOOKUP(O28,index!$Q:$R,2,0) -> 02. 이러닝 - 단과 | O28: 단과 | P28: 없음 | Q28: 01 확정 | R28: =VLOOKUP(C28,'26년 databook(취합)'!$M:$M,2,0) -> #N/A | T28: 1100000 | U28: 1100000 | W28: 0 | Y28: 0 | AA28: 0 | AC28: 0 | AE28: 0 | AG28: 0 | AI28: 1100000 | AK28: 0 | AM28: 0 | AO28: 0 | AQ28: 0 | AS28: 0
A29: 26 | B29: 2025 | C29: 63577-25-001 | D29: 기업교육4팀 | E29: 김성경 | F29: 한국경제인협회 | G29: 63577 | H29: 한국경제인협회 | I29: 63577 | L29: 2025-01-01 00:00:00.0 | M29: 2025-12-31 00:00:00.0 | N29: =VLOOKUP(O29,index!$Q:$R,2,0) -> 02. 이러닝 - 단과 | O29: 단과 | P29: 없음 | Q29: 01 확정 | R29: =VLOOKUP(C29,'26년 databook(취합)'!$M:$M,2,0) -> #N/A | T29: 1730000 | U29: 1730000 | W29: 0 | Y29: 0 | AA29: 0 | AC29: 0 | AE29: 0 | AG29: 0 | AI29: 1730000 | AK29: 0 | AM29: 0 | AO29: 0 | AQ29: 0 | AS29: 0
A30: 27 | B30: 2025 | C30: 58717-25-001 | D30: 기업교육4팀 | E30: 김성경 | F30: C 우선지원기업전용 | G30: 42109 | H30: 웨스코 | I30: 58717 | L30: 2025-01-01 00:00:00.0 | M30: 2025-12-31 00:00:00.0 | N30: =VLOOKUP(O30,index!$Q:$R,2,0) -> 02. 이러닝 - 단과 | O30: 단과 | P30: 없음 | Q30: 01 확정 | R30: =VLOOKUP(C30,'26년 databook(취합)'!$M:$M,2,0) -> #N/A | T30: 220000 | U30: 220000 | W30: 0 | Y30: 0 | AA30: 0 | AC30: 0 | AE30: 0 | AG30: 0 | AI30: 220000 | AK30: 0 | AM30: 0 | AO30: 0 | AQ30: 0 | AS30: 0
A31: 28 | B31: 2025 | C31: 57950-25-001 | D31: 기업교육4팀 | E31: 김성경 | F31: C 우선지원기업전용 | G31: 42109 | H31: 레어마켓 | I31: 57950 | L31: 2025-01-01 00:00:00.0 | M31: 2025-12-31 00:00:00.0 | N31: =VLOOKUP(O31,index!$Q:$R,2,0) -> 02. 이러닝 - 단과 | O31: 단과 | P31: 없음 | Q31: 01 확정 | R31: =VLOOKUP(C31,'26년 databook(취합)'!$M:$M,2,0) -> #N/A | U31: 0
A32: 29 | B32: 2025 | C32: 47998-25-001 | D32: 기업교육4팀 | E32: 김성경 | F32: 에이치피오 | G32: 47998 | H32: 에이치피오 | I32: 47998 | L32: 2025-01-01 00:00:00.0 | M32: 2025-12-31 00:00:00.0 | N32: =VLOOKUP(O32,index!$Q:$R,2,0) -> 02. 이러닝 - 단과 | O32: 단과 | P32: 없음 | Q32: 01 확정 | R32: =VLOOKUP(C32,'26년 databook(취합)'!$M:$M,2,0) -> #N/A | T32: 660000 | U32: 660000 | W32: 0 | Y32: 0 | AA32: 0 | AC32: 0 | AE32: 0 | AG32: 0 | AI32: 660000 | AK32: 0 | AM32: 0 | AO32: 0 | AQ32: 0 | AS32: 0
A33: 30 | B33: 2025 | C33: 43231-25-001 | D33: 기업교육4팀 | E33: 김성경 | F33: C 우선지원기업전용 | G33: 42109 | H33: 제이경인연결고속도로주식회사 | I33: 43231 | J33: 제이경인연결고속도로 | K33: G01519-C02595 | L33: 2025-01-01 00:00:00.0 | M33: 2025-12-31 00:00:00.0 | N33: =VLOOKUP(O33,index!$Q:$R,2,0) -> 02. 이러닝 - 단과 | O33: 단과 | P33: 없음 | Q33: 01 확정 | R33: =VLOOKUP(C33,'26년 databook(취합)'!$M:$M,2,0) -> #N/A | T33: 460000 | U33: 460000 | W33: 0 | Y33: 0 | AA33: 0 | AC33: 0 | AE33: 0 | AG33: 0 | AI33: 460000 | AK33: 0 | AM33: 0 | AO33: 0 | AQ33: 0 | AS33: 0
A34: 31 | B34: 2025 | C34: 42549-25-001 | D34: 기업교육4팀 | E34: 김성경 | F34: C 우선지원기업전용 | G34: 42109 | H34: 비와이케이코리아 | I34: 42549 | J34: 비와이케이코리아 | K34: G01241-C02112 | L34: 2025-01-01 00:00:00.0 | M34: 2025-12-31 00:00:00.0 | N34: =VLOOKUP(O34,index!$Q:$R,2,0) -> 02. 이러닝 - 단과 | O34: 단과 | P34: 없음 | Q34: 01 확정 | R34: =VLOOKUP(C34,'26년 databook(취합)'!$M:$M,2,0) -> #N/A | T34: 432000 | U34: 432000 | W34: 0 | Y34: 0 | AA34: 0 | AC34: 0 | AE34: 0 | AG34: 0 | AI34: 432000 | AK34: 0 | AM34: 0 | AO34: 0 | AQ34: 0 | AS34: 0
A35: 32 | B35: 2025 | C35: 63622-25-001 | D35: 기업교육4팀 | E35: 김성경 | F35: C 우선지원기업전용 | G35: 42109 | H35: 코닉앤바우어케이알 | I35: 63622 | L35: 2025-01-01 00:00:00.0 | M35: 2025-12-31 00:00:00.0 | N35: =VLOOKUP(O35,index!$Q:$R,2,0) -> 01. 이러닝 - 통합위탁 | O35: 통합위탁 | P35: 없음 | Q35: 01 확정 | R35: =VLOOKUP(C35,'26년 databook(취합)'!$M:$M,2,0) -> #N/A | T35: 400000 | U35: 400000 | W35: 0 | Y35: 0 | AA35: 0 | AC35: 0 | AE35: 0 | AG35: 0 | AI35: 400000 | AK35: 0 | AM35: 0 | AO35: 0 | AQ35: 0 | AS35: 0
A36: 33 | B36: 2025 | C36: 63907-25-001 | D36: 기업교육4팀 | E36: 김성경 | F36: C 우선지원기업전용 | G36: 42109 | H36: 한강버스 | I36: 63907 | L36: 2025-01-01 00:00:00.0 | M36: 2025-12-31 00:00:00.0 | N36: =VLOOKUP(O36,index!$Q:$R,2,0) -> 02. 이러닝 - 단과 | O36: 단과 | P36: 없음 | Q36: 01 확정 | R36: =VLOOKUP(C36,'26년 databook(취합)'!$M:$M,2,0) -> #N/A | T36: 160000 | U36: 160000 | W36: 0 | Y36: 0 | AA36: 0 | AC36: 0 | AE36: 0 | AG36: 0 | AI36: 160000 | AK36: 0 | AM36: 0 | AO36: 0 | AQ36: 0 | AS36: 0
A37: 34 | B37: 2025 | C37: 45101-25-001 | D37: 기업교육4팀 | E37: 김성경 | F37: C 우선지원기업전용 | G37: 42109 | H37: 케이씨인터내셔널코리아 | I37: 45101 | J37: 코차이나로지스틱스코리아 | K37: G02164-C03648 | L37: 2025-01-01 00:00:00.0 | M37: 2025-12-31 00:00:00.0 | N37: =VLOOKUP(O37,index!$Q:$R,2,0) -> 02. 이러닝 - 단과 | O37: 단과 | P37: 없음 | Q37: 01 확정 | R37: =VLOOKUP(C37,'26년 databook(취합)'!$M:$M,2,0) -> #N/A | U37: 0
A38: 35 | B38: 2025 | C38: 64003-25-001 | D38: 기업교육4팀 | E38: 김성경 | F38: C 우선지원기업전용 | G38: 42109 | H38: 현대선박기술 | I38: 64003 | L38: 2025-01-01 00:00:00.0 | M38: 2025-12-31 00:00:00.0 | N38: =VLOOKUP(O38,index!$Q:$R,2,0) -> 02. 이러닝 - 단과 | O38: 단과 | P38: 없음 | Q38: 01 확정 | R38: =VLOOKUP(C38,'26년 databook(취합)'!$M:$M,2,0) -> #N/A | U38: 0
A39: 36 | B39: 2025 | C39: 64002-25-001 | D39: 기업교육4팀 | E39: 김성경 | F39: C 우선지원기업전용 | G39: 42109 | H39: 대해선박기술 | I39: 64002 | L39: 2025-01-01 00:00:00.0 | M39: 2025-12-31 00:00:00.0 | N39: =VLOOKUP(O39,index!$Q:$R,2,0) -> 02. 이러닝 - 단과 | O39: 단과 | P39: 없음 | Q39: 01 확정 | R39: =VLOOKUP(C39,'26년 databook(취합)'!$M:$M,2,0) -> #N/A | U39: 0
A40: 37 | B40: 2025 | C40: 47489-25-001 | D40: 기업교육4팀 | E40: 김성경 | F40: 경복궁면세점 | G40: 47489 | H40: 경복궁면세점 | I40: 47489 | L40: 2025-01-01 00:00:00.0 | M40: 2025-12-31 00:00:00.0 | N40: =VLOOKUP(O40,index!$Q:$R,2,0) -> 02. 이러닝 - 단과 | O40: 단과 | P40: 없음 | Q40: 01 확정 | R40: =VLOOKUP(C40,'26년 databook(취합)'!$M:$M,2,0) -> #N/A | T40: 525000 | U40: 525000 | W40: 0 | Y40: 0 | AA40: 0 | AC40: 0 | AE40: 0 | AG40: 0 | AI40: 525000 | AK40: 0 | AM40: 0 | AO40: 0 | AQ40: 0 | AS40: 0
...

Sheet 26년 databook(취합)
D1: FS2팀 데이터북
D2: *공지사항* | W2: 구 분 | Z2: 전주 | AC2: 금주 | AD2: 차이 | AE2: 비고
W3: 유형석 | Z3: 532627500 | AC3: =SUMIFS($AC$21:$AC$653,$Z$21:$Z$653,"01 확정",$G$21:$G$653,W3) -> 536387500 | AD3: =AC3-Z3 -> 3760000
W4: 최상근 | Z4: 1264994000 | AC4: =SUMIFS($AC$21:$AC$653,$Z$21:$Z$653,"01 확정",$G$21:$G$653,W4) -> 1264994000 | AD4: =AC4-Z4 -> 0
W5: 이동호 | Z5: 448455280 | AC5: =SUMIFS($AC$21:$AC$653,$Z$21:$Z$653,"01 확정",$G$21:$G$653,W5) -> 448455280 | AD5: =AC5-Z5 -> 0
W6: 임성은 | Z6: 265249500 | AC6: =SUMIFS($AC$21:$AC$653,$Z$21:$Z$653,"01 확정",$G$21:$G$653,W6) -> 265249500 | AD6: =AC6-Z6 -> 0
W7: 국문정 | Z7: 0 | AC7: =SUMIFS($AC$21:$AC$653,$Z$21:$Z$653,"01 확정",$G$21:$G$653,W7) -> 0 | AD7: 0
W14: 총합계 | Z14: 2511326280 | AC14: =SUM(AC3:AC13) -> 2515086280 | AD14: =AC14-Z14 -> 3760000
W19: ★수정금지★ | X19: ↓수정 금액 작성 | AA19: 추후사용 | AB19: 추후사용
A20: =SUBTOTAL(3,A22:A98330) -> 114 | H20: 추후사용 | L20: 추후사용 | N20: *유형 선택 | O20: *유형 선택 | P20: *유형 선택 | T20: "O"로 표기해주세요. | U20: =SUBTOTAL(9,U636:U1048576) -> 0 | V20: =SUBTOTAL(9,V636:V1048576) -> 0 | W20: =SUBTOTAL(9,W22:W1048576) -> 467603700 | X20: =SUBTOTAL(9,X22:X1048576) -> 0 | Z20: *유형 선택 | AC20: =SUBTOTAL(9,AC22:AC1048576) -> 867137500 | AD20: =SUBTOTAL(9,AD22:AD1048576) -> 1165377500 | AE20: =SUBTOTAL(9,AE22:AE1048576) -> -298240000 | AF20: =SUBTOTAL(9,AF22:AF1048576) -> 253000 | AG20: =SUBTOTAL(9,AG22:AG1048576) -> 21736500 | AH20: =SUBTOTAL(9,AH22:AH1048576) -> 0 | AI20: =SUBTOTAL(9,AI22:AI1048576) -> 9079000 | AJ20: =SUBTOTAL(9,AJ22:AJ1048576) -> 15784000 | ... BF20: =SUBTOTAL(9,BF22:BF1048576) -> 1400000
A21: 고유 번호 | B21: 24년 담당팀 | C21: 24년 영업대표 | D21: 25년 담당팀 | E21: 25년 영업대표 | F21: 26년 최종팀 | G21: 26년 영업대표 (as_is) | H21: 26년 영업대표 (변경 전) | I21: 26년 영업대표 (To_be) | J21: 기업명 (HSM 기준) | K21: 영업기회코드 | L21: 그룹사 | M21: 기업코드 | N21: 기업등급 (신규) | O21: 고객구분 | P21: LMS 상태 | Q21: 24년 사업유형 | R21: 25년 사업유형 | S21: 26년 사업유형 | T21: 핵심 Target R/S 기업 | U21: 23년 매출 | V21: 24년 매출 | W21: 25년 매출 (원본/수정금지) | X21: 25년 매출 수정금액 작성 | Y21: 25년 확정/가망/기회 | Z21: 26년 확정/가망/기회 | AA21: THSM 확/가/기 | AB21: 검수 | AC21: 26년 예상매출합계 | AD21: 전주 | AE21: 차이 | AF21: 1월 예상 | AG21: 1월 마감 | AH21: 1월 매출변동 사유 | AI21: 2월 예상 | AJ21: 2월 마감 | AK21: 2월 매출변동 사유 | AL21: 3월 예상 | AM21: 3월 마감 | AN21: 3월 매출변동 사유 | AO21: 4월 예상 | AP21: 4월 매출변동 사유 | AQ21: 5월 예상 | AR21: 5월 매출변동 사유 | AS21: 6월 예상 | AT21: 6월 매출변동 사유 | AU21: 7월 예상 | AV21: 7월 매출변동 사유 | AW21: 8월 예상 | AX21: 8월 매출변동 사유 | AY21: 9월 예상 | AZ21: 9월 매출변동 사유 | BA21: 10월 예상 | BB21: 10월 매출변동 사유 | BC21: 11월 예상 | BD21: 11월 매출변동 사유 | BE21: 12월 예상 | BF21: 12월 매출변동 사유
A22: 28 | D22: FS팀 | E22: 김지선 | F22: FS2팀 | G22: 유형석 | J22: (주)유베이스 | M22: 977 | N22: 1001~2000 | Q22: 02. 이러닝 - 단과 | R22: 02. 이러닝 - 단과 | S22: 02. 이러닝 - 단과 | W22: 80000000 | Y22: 01 확정 | Z22: 01 확정 | AC22: =AG22+AJ22+AM22+AO22+AQ22+AS22+AU22+AW22+AY22+BA22+BC22+BE22 -> 80000000 | AD22: 80000000 | AE22: =AC22-AD22 -> 0 | AO22: 40000000 | BE22: 40000000
A23: 9 | D23: FS팀 | E23: 유형석 | F23: FS2팀 | G23: 유형석 | J23: (주)삼우종합건축사사무소 | M23: 6706 | N23: 1001~2000 | Q23: 02. 이러닝 - 단과 | R23: 02. 이러닝 - 단과 | S23: 02. 이러닝 - 단과 | W23: 60000000 | Y23: 01 확정 | Z23: 01 확정 | AC23: =AG23+AJ23+AM23+AO23+AQ23+AS23+AU23+AW23+AY23+BA23+BC23+BE23 -> 60000000 | AD23: 60000000 | AE23: =AC23-AD23 -> 0 | AY23: 30000000 | BE23: 30000000
A24: 22 | D24: FS팀 | E24: 유형석 | F24: FS2팀 | G24: 유형석 | J24: (주)아이티엠반도체 | M24: 63288 | N24: 1~1000 | Q24: 26. 이러닝 - 정부지원사업 | R24: 26. 이러닝 - 정부지원사업 | S24: 06. 이러닝 - 정부지원사업 | W24: 34860000 | Y24: 02 가망 | Z24: 01 확정 | AC24: =AG24+AJ24+AM24+AO24+AQ24+AS24+AU24+AW24+AY24+BA24+BC24+BE24 -> 38080000 | AD24: 38080000 | AE24: =AC24-AD24 -> 0 | BC24: 38080000
A25: 53 | D25: FS팀 | E25: 유형석 | F25: FS2팀 | G25: 유형석 | J25: 디알비동일 | M25: 4141 | N25: 1만대 이하 | Q25: 08. 하이브리드러닝 - 하이브리드형 러닝 | R25: 08. 하이브리드러닝 - 하이브리드형 러닝 | S25: 08. 하이브리드러닝 - 하이브리드형 러닝 | W25: 34670000 | Y25: 01 확정 | Z25: 06 사업취소 | AC25: =AG25+AJ25+AM25+AO25+AQ25+AS25+AU25+AW25+AY25+BA25+BC25+BE25 -> 0 | AD25: 0 | AE25: =AC25-AD25 -> 0
A26: 34 | D26: FS팀 | E26: 유형석 | F26: FS2팀 | G26: 유형석 | J26: (주)티와이엠 | M26: 4003 | N26: 1~1000 | Q26: 02. 이러닝 - 단과 | R26: 02. 이러닝 - 단과 | S26: 02. 이러닝 - 단과 | W26: 26200000 | Y26: 01 확정 | Z26: 01 확정 | AC26: =AG26+AJ26+AM26+AO26+AQ26+AS26+AU26+AW26+AY26+BA26+BC26+BE26 -> 30000000 | AD26: 30000000 | AE26: =AC26-AD26 -> 0 | BE26: 30000000
A27: 4 | D27: FS팀 | E27: 유형석 | F27: FS2팀 | G27: 유형석 | J27: (주)동연에스엔티 | M27: 11353 | N27: 1만대 이하 | Q27: 02. 이러닝 - 단과 | R27: 02. 이러닝 - 단과 | S27: 02. 이러닝 - 단과 | W27: 19760000 | Y27: 01 확정 | Z27: 04 실주 | AC27: =AG27+AJ27+AM27+AO27+AQ27+AS27+AU27+AW27+AY27+BA27+BC27+BE27 -> 0 | AD27: 0 | AE27: =AC27-AD27 -> 0
A28: 85 | F28: FS2팀 | G28: 유형석 | J28: 은산해운항공 | M28: 14680 | S28: 02. 이러닝 - 단과 | W28: 17470500 | Z28: 01 확정 | AC28: =AG28+AJ28+AM28+AO28+AQ28+AS28+AU28+AW28+AY28+BA28+BC28+BE28 -> 1700000 | AD28: 1700000 | AE28: =AC28-AD28 -> 0 | AG28: 1700000
A29: 19 | D29: FS팀 | E29: 유형석 | F29: FS2팀 | G29: 유형석 | J29: (주)아이더스에프앤비 | M29: 63423 | N29: 3001~4000 | Q29: 26. 이러닝 - 정부지원사업 | R29: 26. 이러닝 - 정부지원사업 | S29: 06. 이러닝 - 정부지원사업 | W29: 15120000 | Y29: 02 가망 | Z29: 06 사업취소 | AC29: =AG29+AJ29+AM29+AO29+AQ29+AS29+AU29+AW29+AY29+BA29+BC29+BE29 -> 0 | AD29: 0 | AE29: =AC29-AD29 -> 0
A30: 55 | D30: FS팀 | E30: 유형석 | F30: FS2팀 | G30: 유형석 | J30: 디알비동일 | M30: 4141 | N30: 1만대 이하 | Q30: 28.구독 - 휴넷FLEX | R30: 28.구독 - 휴넷FLEX | S30: 13. 구독 - 휴넷FLEX | V30: 7140000 | W30: 15000000 | Y30: 01 확정 | Z30: 01 확정 | AC30: =AG30+AJ30+AM30+AO30+AQ30+AS30+AU30+AW30+AY30+BA30+BC30+BE30 -> 20000000 | AD30: 20000000 | AE30: =AC30-AD30 -> 0 | AO30: 20000000
A31: 95 | D31: 기업교육4팀 | E31: 최재희 | F31: FS2팀 | G31: 유형석 | J31: 티아이씨㈜ | M31: 12194 | N31: 4001~5000 | Q31: 02. 이러닝 - 단과 | R31: 02. 이러닝 - 단과 | S31: 02. 이러닝 - 단과 | V31: 9382000 | W31: 12992000 | Y31: 01 확정 | Z31: 01 확정 | AC31: =AG31+AJ31+AM31+AO31+AQ31+AS31+AU31+AW31+AY31+BA31+BC31+BE31 -> 9050000 | AD31: 9050000 | AE31: =AC31-AD31 -> 0 | AF31: 0 | AJ31: 130000 | AO31: 7920000 | AS31: 0 | AU31: 0 | AW31: 0 | AY31: 1000000 | BA31: 0 | BC31: 0 | BE31: 0
A32: 6 | D32: 기업교육4팀 | E32: 최재희 | F32: FS2팀 | G32: 유형석 | J32: (주)레드캡투어 | M32: 14835 | N32: 1001~2000 | Q32: 03. 이러닝 - 법정 | R32: 03. 이러닝 - 법정 | S32: 03. 이러닝 - 법정 | V32: 5432000 | W32: 9627000 | Y32: 01 확정 | Z32: 01 확정 | AC32: =AG32+AJ32+AM32+AO32+AQ32+AS32+AU32+AW32+AY32+BA32+BC32+BE32 -> 9000000 | AD32: 9000000 | AE32: =AC32-AD32 -> 0 | AF32: 0 | AI32: 0 | AJ32: 0 | AO32: 0 | AQ32: 6000000 | AS32: 0 | AU32: 0 | AW32: 0 | AY32: 0 | BA32: 0 | BC32: 3000000 | BE32: 0
A33: 23 | D33: 기업교육4팀 | E33: 김성경 | F33: FS2팀 | G33: 유형석 | J33: (주)알라딘커뮤니케이션 | M33: 1295 | N33: 1001~2000 | Q33: 02. 이러닝 - 단과 | R33: 02. 이러닝 - 단과 | S33: 02. 이러닝 - 단과 | U33: 6321500 | V33: 0 | W33: 9414000 | Y33: 01 확정 | Z33: 01 확정 | AC33: =AG33+AJ33+AM33+AO33+AQ33+AS33+AU33+AW33+AY33+BA33+BC33+BE33 -> 5000000 | AD33: 5000000 | AE33: =AC33-AD33 -> 0 | AF33: 0 | AO33: 0 | AQ33: 0 | AS33: 0 | AU33: 3000000 | AW33: 0 | AY33: 2000000 | BA33: 0 | BC33: 0 | BE33: 0
A34: 103 | D34: FS팀 | E34: 유형석 | F34: FS2팀 | G34: 유형석 | J34: 한국에스지에스㈜ | M34: 11577 | N34: 2001~3000 | Q34: 28.구독 - 휴넷FLEX | R34: 28.구독 - 휴넷FLEX | S34: 13. 구독 - 휴넷FLEX | W34: 9000000 | Y34: 01 확정 | Z34: 06 사업취소 | AC34: =AG34+AJ34+AM34+AO34+AQ34+AS34+AU34+AW34+AY34+BA34+BC34+BE34 -> 0 | AD34: 0 | AE34: =AC34-AD34 -> 0
A35: 36 | D35: 기업교육4팀 | E35: 하예진 | F35: FS2팀 | G35: 유형석 | J35: (주)해안종합건축사사무소 | M35: 19358 | N35: 2001~3000 | Q35: 08. 하이브리드러닝 - 하이브리드형 러닝 | R35: 08. 하이브리드러닝 - 하이브리드형 러닝 | S35: 03. 이러닝 - 법정 | V35: 4050000 | W35: 8919000 | Y35: 01 확정 | Z35: 01 확정 | AC35: =AG35+AJ35+AM35+AO35+AQ35+AS35+AU35+AW35+AY35+BA35+BC35+BE35 -> 7440000 | AD35: 7440000 | AE35: =AC35-AD35 -> 0 | AM35: 7440000 | AO35: 0 | AQ35: 0 | AS35: 0 | AU35: 0 | AW35: 0 | AY35: 0 | BA35: 0 | BC35: 0 | BE35: 0
A36: 47 | D36: 기업교육4팀 | E36: 하예진 | F36: FS2팀 | G36: 유형석 | J36: 다스코㈜ | M36: 5703 | N36: 1001~2000 | Q36: 02. 이러닝 - 단과 | R36: 02. 이러닝 - 단과 | S36: 02. 이러닝 - 단과 | V36: 21787400 | W36: 8533000 | Y36: 01 확정 | Z36: 01 확정 | AC36: =AG36+AJ36+AM36+AO36+AQ36+AS36+AU36+AW36+AY36+BA36+BC36+BE36 -> 5000000 | AD36: 5000000 | AE36: =AC36-AD36 -> 0 | AF36: 0 | AN36: 4월 교육 오픈 및 청구 | AO36: 5000000 | AQ36: 0 | AU36: 0 | AY36: 0 | BA36: 0 | BC36: 0 | BE36: 0
A37: 102 | D37: FS팀 | E37: 유형석 | F37: FS2팀 | G37: 유형석 | J37: 한국에스지에스㈜ | M37: 11577 | N37: 2001~3000 | Q37: 08. 하이브리드러닝 - 하이브리드형 러닝 | R37: 08. 하이브리드러닝 - 하이브리드형 러닝 | S37: 08. 하이브리드러닝 - 하이브리드형 러닝 | W37: 7932400 | Y37: 01 확정 | Z37: 02 가망 | AC37: =AG37+AJ37+AM37+AO37+AQ37+AS37+AU37+AW37+AY37+BA37+BC37+BE37 -> 8000000 | AD37: 8000000 | AE37: =AC37-AD37 -> 0 | AQ37: 8000000
A38: 12 | D38: 기업교육4팀 | E38: 최수진 | F38: FS2팀 | G38: 유형석 | J38: (주)스포티비 | M38: 31189 | N38: 4001~5000 | Q38: 02. 이러닝 - 단과 | R38: 02. 이러닝 - 단과 | S38: 02. 이러닝 - 단과 | W38: 7776000 | Y38: 01 확정 | Z38: 01 확정 | AC38: =AG38+AJ38+AM38+AO38+AQ38+AS38+AU38+AW38+AY38+BA38+BC38+BE38 -> 5000000 | AD38: 5000000 | AE38: =AC38-AD38 -> 0 | AO38: 0 | AQ38: 0 | AS38: 2000000 | AU38: 0 | AW38: 0 | AY38: 0 | BA38: 0 | BC38: 3000000 | BE38: 0
A39: 15 | D39: FS팀 | E39: 유형석 | F39: FS2팀 | G39: 유형석 | J39: (주)씨티알 | M39: 1705 | N39: 1~1000 | Q39: 02. 이러닝 - 단과 | R39: 02. 이러닝 - 단과 | S39: 02. 이러닝 - 단과 | W39: 6800000 | Y39: 01 확정 | Z39: 01 확정 | AC39: =AG39+AJ39+AM39+AO39+AQ39+AS39+AU39+AW39+AY39+BA39+BC39+BE39 -> 6000000 | AD39: 6000000 | AE39: =AC39-AD39 -> 0 | AS39: 6000000
A40: 1 | D40: 기업교육4팀 | E40: 최재희 | F40: FS2팀 | G40: 유형석 | J40: (주)다스 | M40: 3226 | N40: 1~1000 | Q40: 08. 하이브리드러닝 - 하이브리드형 러닝 | R40: 08. 하이브리드러닝 - 하이브리드형 러닝 | S40: 08. 하이브리드러닝 - 하이브리드형 러닝 | U40: 5420000 | V40: 21170000 | W40: 6330800 | Y40: 02 가망 | Z40: 01 확정 | AC40: =AG40+AJ40+AM40+AO40+AQ40+AS40+AU40+AW40+AY40+BA40+BC40+BE40 -> 12250000 | AD40: 12250000 | AE40: =AC40-AD40 -> 0 | AG40: 12250000 | AI40: 0 | AJ40: 0 | AO40: 0 | AQ40: 0 | AS40: 0 | AW40: 0 | AY40: 0 | BA40: 0 | BC40: 0 | BE40: 0
A41: 7 | D41: FS팀 | E41: 유형석 | F41: FS2팀 | G41: 유형석 | J41: (주)비와이엔블랙야크 | M41: 15169 | N41: 1001~2000 | Q41: 09. 하이브리드러닝 - 순수 오프라인 | R41: 09. 하이브리드러닝 - 순수 오프라인 | S41: 09. 하이브리드러닝 - 순수 오프라인 | W41: 5500000 | Y41: 01 확정 | Z41: 01 확정 | AC41: =AG41+AJ41+AM41+AO41+AQ41+AS41+AU41+AW41+AY41+BA41+BC41+BE41 -> 5000000 | AD41: 5000000 | AE41: =AC41-AD41 -> 0 | AQ41: 5000000
A42: 26 | D42: FS팀 | E42: 유형석 | F42: FS2팀 | G42: 유형석 | J42: (주)애큐온캐피탈 | M42: 10415 | N42: 1001~2000 | Q42: 09. 하이브리드러닝 - 순수 오프라인 | R42: 09. 하이브리드러닝 - 순수 오프라인 | S42: 09. 하이브리드러닝 - 순수 오프라인 | W42: 4940000 | Y42: 02 가망 | Z42: 01 확정 | AC42: =AG42+AJ42+AM42+AO42+AQ42+AS42+AU42+AW42+AY42+BA42+BC42+BE42 -> 1290000 | AD42: 1290000 | AE42: =AC42-AD42 -> 0 | AM42: 1290000
A43: 106 | F43: FS2팀 | G43: 유형석 | J43: 한살림연합회_A25 | M43: 64820 | S43: 06. 이러닝 - 정부지원사업 | W43: 4760000 | Y43: 01 확정 | AC43: =AG43+AJ43+AM43+AO43+AQ43+AS43+AU43+AW43+AY43+BA43+BC43+BE43 -> 0 | AD43: 0 | AE43: =AC43-AD43 -> 0
A44: 38 | D44: 기업교육4팀 | E44: 하예진 | F44: FS2팀 | G44: 유형석 | J44: [57974]이베이재팬 | M44: 57974 | Q44: 1. 온라인 - 단과 | R44: 02. 이러닝 - 단과 | S44: 02. 이러닝 - 단과 | V44: 3060000 | W44: 3675000 | Y44: 02 가망 | Z44: 03 기회 | AC44: =AG44+AJ44+AM44+AO44+AQ44+AS44+AU44+AW44+AY44+BA44+BC44+BE44 -> 0 | AD44: 0 | AE44: =AC44-AD44 -> 0 | AF44: 0 | AI44: 0 | AJ44: 0 | AO44: 0 | AQ44: 0 | AS44: 0 | AU44: 0 | AW44: 0 | AY44: 0 | BA44: 0 | BC44: 0 | BE44: 0
A45: 37 | D45: 기업교육4팀 | E45: 하예진 | F45: FS2팀 | G45: 유형석 | J45: (주)해안종합건축사사무소 | M45: 19358 | N45: 2001~3000 | Q45: 08. 하이브리드러닝 - 하이브리드형 러닝 | R45: 08. 하이브리드러닝 - 하이브리드형 러닝 | S45: 08. 하이브리드러닝 - 하이브리드형 러닝 | V45: 4050000 | W45: 3600000 | Y45: 01 확정 | Z45: 01 확정 | AC45: =AG45+AJ45+AM45+AO45+AQ45+AS45+AU45+AW45+AY45+BA45+BC45+BE45 -> 0 | AD45: 0 | AE45: =AC45-AD45 -> 0 | AF45: 0 | AI45: 3000000 | AO45: 0 | AQ45: 0 | AS45: 0 | AU45: 0 | AW45: 0 | AY45: 0 | BA45: 0 | BC45: 0 | BE45: 0
A46: 72 | D46: FS팀 | E46: 유형석 | F46: FS2팀 | G46: 유형석 | J46: 에스넷시스템㈜ | M46: 63442 | N46: 1001~2000 | Q46: 03. 이러닝 - 법정 | R46: 03. 이러닝 - 법정 | S46: 03. 이러닝 - 법정 | W46: 3534000 | Y46: 01 확정 | Z46: 01 확정 | AC46: =AG46+AJ46+AM46+AO46+AQ46+AS46+AU46+AW46+AY46+BA46+BC46+BE46 -> 5035000 | AD46: 5035000 | AE46: =AC46-AD46 -> 0 | AJ46: 35000 | BE46: 5000000
A47: 54 | D47: FS팀 | E47: 유형석 | F47: FS2팀 | G47: 유형석 | J47: 디알비동일 | M47: 4141 | N47: 1만대 이하 | Q47: 09. 하이브리드러닝 - 순수 오프라인 | R47: 09. 하이브리드러닝 - 순수 오프라인 | S47: 09. 하이브리드러닝 - 순수 오프라인 | W47: 3500000 | Y47: 01 확정 | Z47: 01 확정 | AC47: =AG47+AJ47+AM47+AO47+AQ47+AS47+AU47+AW47+AY47+BA47+BC47+BE47 -> 4000000 | AD47: 4000000 | AE47: =AC47-AD47 -> 0 | AU47: 4000000
A48: 105 | F48: FS2팀 | G48: 유형석 | J48: 한살림사업연합_A25 | M48: 64821 | S48: 06. 이러닝 - 정부지원사업 | W48: 3444000 | Y48: 01 확정 | AC48: =AG48+AJ48+AM48+AO48+AQ48+AS48+AU48+AW48+AY48+BA48+BC48+BE48 -> 0 | AD48: 0 | AE48: =AC48-AD48 -> 0
A49: 10 | D49: FS팀 | E49: 유형석 | F49: FS2팀 | G49: 유형석 | J49: (주)삼우종합건축사사무소 | M49: 6706 | N49: 1001~2000 | Q49: 09. 하이브리드러닝 - 순수 오프라인 | R49: 09. 하이브리드러닝 - 순수 오프라인 | S49: 09. 하이브리드러닝 - 순수 오프라인 | W49: 2800000 | Y49: 01 확정 | Z49: 01 확정 | AC49: =AG49+AJ49+AM49+AO49+AQ49+AS49+AU49+AW49+AY49+BA49+BC49+BE49 -> 2680000 | AD49: 2680000 | AE49: =AC49-AD49 -> 0 | AG49: 2680000
A50: 31 | D50: FS팀 | E50: 유형석 | F50: FS2팀 | G50: 유형석 | J50: (주)제니엘 | M50: 5542 | N50: 2001~3000 | Q50: 09. 하이브리드러닝 - 순수 오프라인 | R50: 09. 하이브리드러닝 - 순수 오프라인 | S50: 09. 하이브리드러닝 - 순수 오프라인 | W50: 2720000 | Y50: 01 확정 | Z50: 01 확정 | AC50: =AG50+AJ50+AM50+AO50+AQ50+AS50+AU50+AW50+AY50+BA50+BC50+BE50 -> 2800000 | AD50: 2800000 | AE50: =AC50-AD50 -> 0 | AM50: 2800000
...

Sheet 수정사항
A1: 고유 번호 | B1: 25년 담당팀 | C1: 25년 영업대표 | D1: 기업명 (HSM 기준) | E1: 영업기회코드 | F1: 기업코드 | G1: 25년 사업유형 | H1: 23년 매출 | I1: 24년 매출 | J1: 25년 확정/가망/기회 | K1: THSM 확/가/기 | L1: 25년 예상매출합계 | M1: THSM
A2: 11 | B2: 기업교육4팀 | C2: 김두희 | D2: [11259]노사발전재단 | E2: 11259-25-004 | F2: 11259 | G2: 15. 솔루션 - LABS | H2: 18000000 | I2: 0 | J2: 07 2023년 매출 | K2: 03 기회 | L2: 26000000 | M2: 지울수 있는가
A3: 1365 | B3: 기업교육4팀 | C3: 하예진 | D3: [3157]한국산업기술시험원 | E3: 3157-25-002 | F3: 3157 | G3: 25. 기타 - 기타 | H3: 812000 | I3: 0 | J3: 01 확정 | K3: 01 확정 | L3: 1260000 | M3: 사업유형 변경
A4: 추가0408 | B4: 기업교육4팀 | C4: 최수진 | D4: 삼십팔인의 교육생각 | E4: 30370-25-001 | F4: 30370 | G4: 25. 기타 - 기타 | J4: 01 확정 | K4: 01 확정 | L4: 264000 | M4: 사업유형 변경
A5: 추가0513 | B5: 기업교육4팀 | C5: 양은희 | D5: 재단법인 병원약학교육연구원(한국병원약사회 산하) | E5: 22127-25-001 | F5: 22127 | G5: 14. 컨텐츠 - 컨텐츠 개발 | J5: 01 확정 | L5: 27300000 | M5: 영업대표 변경
A6: 1036 | B6: 기업교육4팀 | C6: 김성경 | D6: 금강이엠씨 | E6: 47852-25-002 | F6: 47852 | G6: 19. 운영 - 운영매출 | I6: 406,000 | J6: 01 확정 | K6: 01 확정 | L6: 406000 | M6: 사업유형 변경
A7: 1328 | B7: 기업교육4팀 | C7: 김성경 | D7: 현대팜아카데미 | E7: 16402-25-002 | F7: 16402 | G7: 19. 운영 - 운영매출 | I7: - | J7: 01 확정 | K7: 01 확정 | L7: 0 | M7: 사업유형 변경
A8: 3371 | B8: 기업교육4팀 | C8: 양은희 | D8: 대한병원협회 | E8: 16094-25-002 | F8: 16094 | G8: 19. 운영 - 운영매출 | I8: 33,636,365 | J8: 01 확정 | K8: 01 확정 | L8: 60000000 | M8: 사업유형 변경
A9: 3372 | B9: 기업교육4팀 | C9: 양은희 | D9: 대한병원협회 | E9: 16094-25-003 | F9: 16094 | G9: 19. 운영 - 운영매출 | I9: - | J9: 01 확정 | K9: 01 확정 | L9: 0 | M9: 사업유형 변경
A10: 추가0311 | B10: 기업교육4팀 | C10: 김성경 | D10: 나이스디앤비(ESG사업) | E10: 52519-25-001 | F10: 52519 | G10: 19. 운영 - 운영매출 | J10: 01 확정 | K10: 01 확정 | L10: 2200000 | M10: 사업유형 변경

Sheet 영업대표별
B3: FS2팀 | C3: 25년 매출 | D3: 26년 개인별 목표 | E3: '26년 (1~12월) | M3: 전주대비 확정차 | N3: 전주 대비 확정 차이 내역 | O3: 목표 달성율 (확정만)
E4: 전주 | I4: 금주
E5: 계 | F5: 확정 | G5: 가망 | H5: 기회 | I5: 계 | J5: 확정 | K5: 가망 | L5: 기회
B6: 유형석 | E6: 1165377500 | F6: 532627500 | G6: 134750000 | H6: 498000000 | I6: =SUM(J6:L6) -> 1165377500 | J6: 532627500 | K6: 134750000 | L6: 498000000 | M6: =J6-F6 -> 0 | N6: ='26년 databook(취합)'!AE3 -> 0 | O6: =J6/D6 -> #DIV/0!
B7: 최상근 | E7: 2179301756 | F7: 1264994000 | G7: 453387756 | H7: 460920000 | I7: =SUM(J7:L7) -> 2179301756 | J7: 1264994000 | K7: 453387756 | L7: 460920000 | M7: =J7-F7 -> 0 | N7: ='26년 databook(취합)'!AE4 -> 0 | O7: =J7/D7 -> #DIV/0!
B8: 이동호 | E8: 1441797280 | F8: 448455280 | G8: 161642000 | H8: 831700000 | I8: =SUM(J8:L8) -> 1441797280 | J8: 448455280 | K8: 161642000 | L8: 831700000 | M8: =J8-F8 -> 0 | N8: ='26년 databook(취합)'!AE5 -> 0 | O8: =J8/D8 -> #DIV/0!
B9: 임성은 | E9: 703849500 | F9: 265249500 | G9: 166600000 | H9: 272000000 | I9: =SUM(J9:L9) -> 703849500 | J9: 265249500 | K9: 166600000 | L9: 272000000 | M9: =J9-F9 -> 0 | N9: ='26년 databook(취합)'!AE6 -> 0 | O9: =J9/D9 -> #DIV/0!
B10: 국문정 | F10: 1000000 | J10: 1000000 | M10: =J10-F10 -> 0 | N10: ='26년 databook(취합)'!AE7 -> 0 | O10: =J10/D10 -> #DIV/0!
E11: 0 | I11: =SUM(J11:L11) -> 0 | M11: =J11-F11 -> 0 | N11: ='26년 databook(취합)'!AE8 -> 0 | O11: =J11/D11 -> #DIV/0!
E12: 0 | I12: =SUM(J12:L12) -> 0 | M12: =J12-F12 -> 0 | N12: ='26년 databook(취합)'!AE9 -> 0 | O12: =J12/D12 -> #DIV/0!
E13: 0 | I13: =SUM(J13:L13) -> 0 | M13: =J13-F13 -> 0 | N13: ='26년 databook(취합)'!AE10 -> 0 | O13: =J13/D13 -> #DIV/0!
E14: 0 | I14: =SUM(J14:L14) -> 0 | M14: =J14-F14 -> 0 | N14: ='26년 databook(취합)'!AE11 -> 0 | O14: =J14/D14 -> #DIV/0!
E15: 0 | I15: =SUM(J15:L15) -> 0 | M15: =J15-F15 -> 0
E16: 0 | I16: =SUM(J16:L16) -> 0 | M16: =J16-F16 -> 0
B17: 총계 | C17: =SUM(C6:C14) -> 0 | E17: 5490326036 | F17: 2512326280 | G17: 916379756 | H17: 2062620000 | I17: =SUM(I6:I16) -> 5490326036 | J17: =SUM(J6:J16) -> 2512326280 | K17: =SUM(K6:K16) -> 916379756 | L17: =SUM(L6:L16) -> 2062620000 | M17: =SUM(M6:M16) -> 0 | O17: =J17/D17 -> #DIV/0!

Sheet 팀연간
T1: 100000
R2: 단위:백만원)
B3: 구분 | D3: 2026년 월별 연간 | Q3: 전주 보고
D4: 1월 | E4: 2월 | F4: 3월 | G4: 4월 | H4: 5월 | I4: 6월 | J4: 7월 | K4: 8월 | L4: 9월 | M4: 10월 | N4: 11월 | O4: 12월 | P4: 금주계 | Q4: 전주 계 | R4: 전주차
B5: 2025년 실적
B6: 2026년 목표 | D6: 100000000 | E6: 140000000 | F6: 180000000 | G6: 210000000 | H6: 250000000 | I6: 280000000 | J6: 290000000 | K6: 300000000 | L6: 320000000 | M6: 330000000 | N6: 340000000 | O6: 350000000 | P6: =SUM(D6:O6) -> 3090000000 | Q6: 3090000000
B7: 2026년 전망 | C7: (확정+가망) | D7: =D8+D9 -> 84721500 | E7: =E8+E9 -> 48295800 | F7: =F8+F9 -> 79332700 | G7: =G8+G9 -> 417764500 | H7: =H8+H9 -> 218752000 | I7: =I8+I9 -> 175417000 | J7: =J8+J9 -> 86530000 | K7: =K8+K9 -> 348740000 | ... O7: =O8+O9 -> 1412323256 | P7: =SUM(D7:O7) -> 3428706036 | Q7: 3428706036 | R7: =P7-Q7 -> 0
C8: 확정 | D8: 84721500 | E8: 48295800 | F8: 79332700 | G8: 409414500 | H8: 54660000 | I8: 108067000 | J8: 51500000 | K8: 277390000 | L8: 71390000 | M8: 72295000 | N8: 164494280 | O8: 1090765500 | P8: =SUM(D8:O8) -> 2512326280 | Q8: 2512326280 | R8: =P8-Q8 -> 0
C9: 가망 | D9: 0 | E9: 0 | G9: 8350000 | H9: 164092000 | I9: 67350000 | J9: 35030000 | K9: 71350000 | L9: 82350000 | M9: 81350000 | N9: 84950000 | O9: 321557756 | P9: =SUM(D9:O9) -> 916379756 | Q9: 916379756 | R9: =P9-Q9 -> 0
C10: 기회 | D10: 0 | E10: 0 | G10: 0 | H10: 546500000 | I10: 275000000 | J10: 150000000 | K10: 45600000 | L10: 32000000 | M10: 180000000 | N10: 178000000 | O10: 655520000 | P10: =SUM(D10:O10) -> 2062620000 | Q10: 2062620000 | R10: =P10-Q10 -> 0
C11: (확정+가망+기회) | D11: =SUM(D8:D10) -> 84721500 | E11: =SUM(E8:E10) -> 48295800 | F11: =SUM(F8:F10) -> 79332700 | G11: =SUM(G8:G10) -> 417764500 | H11: =SUM(H8:H10) -> 765252000 | I11: =SUM(I8:I10) -> 450417000 | J11: =SUM(J8:J10) -> 236530000 | K11: =SUM(K8:K10) -> 394340000 | ... O11: =SUM(O8:O10) -> 2067843256 | P11: =P8+P9+P10 -> 5491326036 | Q11: 5491326036 | R11: =P11-Q11 -> 0
C12: 달성률(목표대비) | D12: =D8/D6 -> 0.847215 | E12: =E8/E6 -> 0.34497 | F12: =F8/F6 -> 0.44073722 | G12: =G8/G6 -> 1.9495929 | H12: =H8/H6 -> 0.21864 | I12: =I8/I6 -> 0.38595357 | J12: =J8/J6 -> 0.17758621 | K12: =K8/K6 -> 0.92463333 | ... P12: =P8/P6 -> 0.81305058 | Q12: 0.59466333

Sheet 마감내역
B2: 1월 | C2: =SUM(C4:C341) -> 370529249 | E2: 2월 | F2: =SUM(F4:F400) -> 479113404 | H2: 3월 | I2: =SUM(I4:I4001) -> 995108623 | K2: 4월 | L2: =SUM(L4:L4000) -> 878433688 | N2: 5월 | O2: =SUM(O4:O3999) -> 841788881
B3: 행 레이블 | C3: 합계 : 판매금액 | E3: 행 레이블 | F3: 합계 : 판매금액 | H3: 행 레이블 | I3: 합계 : 판매금액 | K3: 행 레이블 | L3: 합계 : 판매금액 | N3: 행 레이블 | O3: 합계 : 판매금액
B4: 10337-25-001 | C4: 4080000 | E4: 10336-25-001 | F4: 4800000 | H4: 10273-25-001 | I4: 380000 | K4: 1005-25-001 | L4: 1668000 | N4: 1021-25-001 | O4: 1252000
B5: 1034-25-001 | C5: 174000 | E5: 1034-25-001 | F5: 590000 | H5: 1034-25-001 | I5: 132000 | K5: 10122-25-001 | L5: 405000 | N5: 10281-25-002 | O5: 1200000
B6: 10722-25-001 | C6: 2565600 | E6: 11673-25-001 | F6: 285000 | H6: 10651-25-001 | I6: 33454545 | K6: 1021-25-001 | L6: 40000 | N6: 10286-25-001 | O6: 80000
B7: 1097-25-001 | C7: 260000 | E7: 11829-25-001 | F7: 6000 | H7: 10863-25-001 | I7: 63000 | K7: 10281-25-002 | L7: 1200000 | N7: 1034-25-001 | O7: 329000
B8: 11673-25-001 | C8: 310000 | E8: 1188-25-001 | F8: 70000 | H8: 11214-25-001 | I8: 180000 | K8: 1031-25-003 | L8: 20000 | N8: 10441-25-001 | O8: 135000
B9: 11702-25-001 | C9: 15000 | E9: 12899-25-003 | F9: 20000 | H9: 11329-25-001 | I9: 10400000 | K9: 1034-25-001 | L9: 180000 | N9: 11066-25-001 | O9: 360000
B10: 11714-25-001 | C10: 330000 | E10: 1295-25-001 | F10: 1200000 | H10: 11329-25-002 | I10: 1800000 | K10: 10376-25-002 | L10: 4360000 | N10: 11232-25-001 | O10: 1165000
B11: 12146-25-001 | C11: 84000 | E11: 13114-25-001 | F11: 18000 | H11: 11673-25-001 | I11: 766000 | K11: 10441-25-001 | L11: 1441000 | N11: 11409-25-001 | O11: 1261500
B12: 13114-25-001 | C12: 42000 | E12: 13661-25-001 | F12: 2067600 | H12: 11702-25-001 | I12: 135000 | K12: 1063-25-002 | L12: 155000 | N12: 11673-25-001 | O12: 421000
B13: 13661-25-001 | C13: 1988500 | E13: 13668-25-001 | F13: 5000 | H13: 11829-25-001 | I13: 3192000 | K13: 10733-25-001 | L13: 4632727 | N13: 11702-25-001 | O13: 220000
B14: 13751-25-001 | C14: 370000 | E14: 13751-25-001 | F14: 1544600 | H14: 1188-25-001 | I14: 5175000 | K14: 11049-25-001 | L14: 1992000 | N14: 11829-25-002 | O14: 57000
B15: 14074-25-001 | C15: 71060 | E15: 14349-25-001 | F15: 100000 | H15: 12899-25-003 | I15: 120000 | K15: 11209-25-001 | L15: 3600000 | N15: 12057-25-001 | O15: 250000
... B231: 181-25-001 | C231: 90500 | E231: 40318-25-001 | F231: 20000 | H231: 9598-25-002 | I231: 1600000 | K231: 28933-25-001 | L231: 2776000 | N231: 30230-25-001 | O231: 1736000
B232: 650-25-001 | C232: 271200 | E232: 43611-25-001 | F232: -701500 | H232: 9602-25-003 | I232: =3500000+1500000 -> 5000000 | K232: 28975-25-001 | L232: 52000 | N232: 3050-25-001 | O232: 1239800
B233: 1547-25-001 | C233: 26000 | E233: 18701-25-001 | F233: 46000 | H233: 9634-25-001 | I233: 30000 | K233: 28977-25-001 | L233: 80000 | N233: 30593-25-001 | O233: 468000
B234: 1600-25-001 | C234: 445000 | E234: 18444-25-001 | F234: 676000 | H234: 9663-25-001 | I234: 1091000 | K234: 29104-25-002 | L234: 20000 | N234: 30623-25-001 | O234: 798000
B235: 1984-25-001 | C235: 80000 | E235: 29134-25-001 | F235: 825000 | H235: 9685-25-001 | I235: 50000 | K235: 29134-25-001 | L235: 75000 | N235: 31524-25-002 | O235: 780000
B236: 3050-25-001 | C236: 50000 | E236: 17060-25-001 | F236: 390000 | H236: 983-25-001 | I236: 1464000 | K236: 29245-25-001 | L236: 20000 | N236: 31591-25-002 | O236: 8000
B237: 3103-25-001 | C237: 617000 | E237: 9594-25-001 | F237: 1136000 | H237: 9602-25-001 | I237: =283115000-1500000 -> 281615000 | K237: 29262-25-001 | L237: 2200000 | N237: 31721-25-001 | O237: 2232000
B238: 4194-25-001 | C238: 855000 | E238: 7994-25-001 | F238: 380000 | H238: 20339-25-001 | I238: 2000000 | K238: 2931-25-001 | L238: 427000 | N238: 32046-25-001 | O238: 1135000
B239: 4617-25-001 | C239: 2104000 | E239: 5205-25-001 | F239: 70000 | H239: 18789-25-001 | I239: 670000 | K239: 2952-25-002 | L239: 130000 | N239: 32129-25-001 | O239: 2250000
B240: 5169-25-001 | C240: 169800 | E240: 7387-25-001 | F240: 695000 | H240: 48481-25-001 | I240: 599000 | K240: 29752-25-001 | L240: 1760000 | N240: 32189-25-002 | O240: 300000
B241: 5594-25-001 | C241: 505000 | E241: 650-25-001 | F241: 601000 | H241: 7357-25-001 | I241: 2411700 | K241: 30197-25-001 | L241: 769000 | N241: 3226-25-001 | O241: 624000
B242: 6755-25-001 | C242: 120000 | E242: 924-25-001 | F242: 220000 | H242: 17423-25-001 | I242: 483000 | K242: 3034-25-001 | L242: 275000 | N242: 32277-25-001 | O242: 60000
B243: 7036-25-001 | C243: 270000 | E243: 1547-25-001 | F243: 600000 | H243: 21802-25-001 | I243: 889000 | K243: 3034-25-002 | L243: 2600000 | N243: 3317-25-001 | O243: 820000
B244: 7836-25-001 | C244: 894000 | E244: 1600-25-001 | F244: 964700 | H244: 30141-25-001 | I244: 30000 | K244: 30358-25-001 | L244: 0 | N244: 3421-25-001 | O244: 120000
B245: 8574-25-001 | C245: 582800 | E245: 1663-25-001 | F245: 60000 | H245: 42453-25-001 | I245: 1340000 | K245: 3050-25-001 | L245: 1844000 | N245: 36398-25-001 | O245: 56000
B246: 9103-25-001 | C246: 1228900 | E246: 1984-25-001 | F246: 400000 | H246: 12976-25-001 | I246: 50000 | K246: 30593-25-001 | L246: 932000 | N246: 3650-25-001 | O246: 105000
B247: 9452-25-001 | C247: 107000 | E247: 2648-25-001 | F247: 120000 | H247: 61261-25-001 | I247: 700000 | K247: 30672-25-001 | L247: 8050000 | N247: 3927-25-001 | O247: 320000
B248: 9731-25-001 | C248: 1960000 | E248: 2771-25-001 | F248: 345000 | H248: 61323-25-001 | I248: 7140000 | K248: 31524-25-002 | L248: 485000 | N248: 39942-25-003 | O248: 135000
B249: 10052-25-001 | C249: 120000 | E249: 3050-25-001 | F249: 858000 | H249: 61325-25-001 | I249: 840000 | K249: 31967-25-001 | L249: 1290000 | N249: 40063-25-002 | O249: 246000
... B341: 1930-25-001 | C341: 2260000 | E341: 14924-25-001 | F341: 2040000 | H341: 19158-25-001 | I341: 1512000 | K341: 45956-25-001 | L341: 1799000 | N341: 49111-25-001 | O341: 30000
E342: 16792-25-001 | F342: 2451000 | H342: 19569-25-001 | I342: 1066800 | K342: 45957-25-001 | L342: 2145000 | N342: 49155-25-001 | O342: 1350000
E343: 26529-25-001 | F343: 790000 | H343: 20362-25-001 | I343: 50000 | K343: 45969-25-001 | L343: 170000 | N343: 49316-25-002 | O343: 4000
E344: 27358-25-001 | F344: 20000 | H344: 20430-25-001 | I344: 1385000 | K344: 4598-25-002 | L344: 5237000 | N344: 49423-25-001 | O344: 700000
E345: 30130-25-001 | F345: 360000 | H345: 20493-25-001 | I345: 75000 | K345: 46085-25-001 | L345: 15000 | N345: 49580-25-001 | O345: 976000
E346: 43207-25-001 | F346: 150000 | H346: 20879-25-001 | I346: 60000 | K346: 46094-25-001 | L346: 80000 | N346: 49640-25-001 | O346: 60000
E347: 53395-25-001 | F347: 30000 | H347: 21222-25-001 | I347: 120000 | K347: 46100-25-001 | L347: 23015750 | N347: 49678-25-001 | O347: 5097800
...

Sheet HSM비교
B2: 월별 | C2: 5월 | G2: 2월 | K2: 3월 | O2: 4월 | S2: 5월 | W2: 6월 | AA2: 7월 | AE2: 8월 | AI2: 9월 | AM2: 10월 | AQ2: 11월 | AU2: 12월
B3: 영업대표 | C3: 데이터북(0602기준) | D3: ERP 마감 | E3: 차액 | F3: 비고 | G3: 데이터북(매출란) | H3: ERP 마감 | I3: 차액 | J3: 비고 | K3: 데이터북(매출란) | L3: ERP 마감 | M3: 차액 | N3: 비고 | O3: 데이터북(매출란) | P3: ERP 마감 | Q3: 차액 | R3: 비고 | S3: 데이터북(매출란) | T3: ERP 마감 | U3: 차액 | V3: 비고 | W3: 데이터북(매출란) | X3: ERP 마감 | Y3: 차액 | Z3: 비고 | AA3: 데이터북(매출란) | AB3: ERP 마감 | AC3: 차액 | AD3: 비고 | AE3: 데이터북(매출란) | AF3: ERP 마감 | AG3: 차액 | AH3: 비고 | AI3: 데이터북(매출란) | AJ3: ERP 마감 | AK3: 차액 | AL3: 비고 | AM3: 데이터북(매출란) | AN3: ERP 마감 | AO3: 차액 | AP3: 비고 | AQ3: 데이터북(매출란) | AR3: ERP 마감 | AS3: 차액 | AT3: 비고 | AU3: 데이터북(매출란) | AV3: ERP 마감 | AW3: 차액 | AX3: 비고
B4: 김두희 | C4: 101543800 | D4: 166106718 | E4: =D4-C4 -> 64562918 | I4: =G4-H4 -> 0 | M4: =K4-L4 -> 0 | Q4: =O4-P4 -> 0 | U4: =S4-T4 -> 0 | Y4: =W4-X4 -> 0 | AC4: =AA4-AB4 -> 0 | AG4: =AE4-AF4 -> 0 | AK4: =AI4-AJ4 -> 0 | AO4: =AM4-AN4 -> 0 | AS4: =AQ4-AR4 -> 0 | AW4: =AU4-AV4 -> 0
B5: 이나래 | C5: 102100000 | D5: 85152690 | E5: =D5-C5 -> -16947310 | I5: =G5-H5 -> 0 | M5: =K5-L5 -> 0 | Q5: =O5-P5 -> 0 | U5: =S5-T5 -> 0 | Y5: =W5-X5 -> 0 | AC5: =AA5-AB5 -> 0 | AG5: =AE5-AF5 -> 0 | AK5: =AI5-AJ5 -> 0 | AO5: =AM5-AN5 -> 0 | AS5: =AQ5-AR5 -> 0 | AW5: =AU5-AV5 -> 0
B6: 최재희 | C6: 20600000 | D6: 117431900 | E6: =D6-C6 -> 96831900 | I6: =G6-H6 -> 0 | M6: =K6-L6 -> 0 | Q6: =O6-P6 -> 0 | U6: =S6-T6 -> 0 | Y6: =W6-X6 -> 0 | AC6: =AA6-AB6 -> 0 | AG6: =AE6-AF6 -> 0 | AK6: =AI6-AJ6 -> 0 | AO6: =AM6-AN6 -> 0 | AS6: =AQ6-AR6 -> 0 | AW6: =AU6-AV6 -> 0
B7: 김성경 | C7: 30497000 | D7: 75475100 | E7: =D7-C7 -> 44978100 | I7: =G7-H7 -> 0 | M7: =K7-L7 -> 0 | Q7: =O7-P7 -> 0 | U7: =S7-T7 -> 0 | Y7: =W7-X7 -> 0 | AC7: =AA7-AB7 -> 0 | AG7: =AE7-AF7 -> 0 | AK7: =AI7-AJ7 -> 0 | AO7: =AM7-AN7 -> 0 | AS7: =AQ7-AR7 -> 0 | AW7: =AU7-AV7 -> 0
B8: 하예진 | C8: 127321333 | D8: 117225282 | E8: =D8-C8 -> -10096051 | I8: =G8-H8 -> 0 | M8: =K8-L8 -> 0 | Q8: =O8-P8 -> 0 | U8: =S8-T8 -> 0 | Y8: =W8-X8 -> 0 | AC8: =AA8-AB8 -> 0 | AG8: =AE8-AF8 -> 0 | AK8: =AI8-AJ8 -> 0 | AO8: =AM8-AN8 -> 0 | AS8: =AQ8-AR8 -> 0 | AW8: =AU8-AV8 -> 0
B9: 최수진 | C9: 29985000 | D9: 90244700 | E9: =D9-C9 -> 60259700 | I9: =G9-H9 -> 0 | M9: =K9-L9 -> 0 | Q9: =O9-P9 -> 0 | U9: =S9-T9 -> 0 | Y9: =W9-X9 -> 0 | AC9: =AA9-AB9 -> 0 | AG9: =AE9-AF9 -> 0 | AK9: =AI9-AJ9 -> 0 | AO9: =AM9-AN9 -> 0 | AS9: =AQ9-AR9 -> 0 | AW9: =AU9-AV9 -> 0
B10: 방유진 | C10: 75130000 | D10: 98735450 | E10: =D10-C10 -> 23605450
B11: 양은희 | D11: 91342860
B12: 제휴 | D12: 74181 | I12: =G12-H12 -> 0 | M12: =K12-L12 -> 0 | Q12: =O12-P12 -> 0 | U12: =S12-T12 -> 0 | Y12: =W12-X12 -> 0 | AC12: =AA12-AB12 -> 0 | AG12: =AE12-AF12 -> 0 | AK12: =AI12-AJ12 -> 0 | AO12: =AM12-AN12 -> 0 | AS12: =AQ12-AR12 -> 0 | AW12: =AU12-AV12 -> 0
B13: 합계 | C13: =SUM(C4:C12) -> 487177133 | D13: =SUM(D4:D12) -> 841788881 | E13: =SUM(E4:E12) -> 263194707 | G13: =SUM(G4:G12) -> 0 | H13: =SUM(H4:H12) -> 0 | I13: =SUM(I4:I12) -> 0 | K13: =SUM(K4:K12) -> 0 | L13: =SUM(L4:L12) -> 0 | M13: =SUM(M4:M12) -> 0 | O13: =SUM(O4:O12) -> 0 | P13: =SUM(P4:P12) -> 0 | Q13: =SUM(Q4:Q12) -> 0 | S13: =SUM(S4:S12) -> 0 | T13: =SUM(T4:T12) -> 0 | U13: =SUM(U4:U12) -> 0 | W13: =SUM(W4:W12) -> 0 | X13: =SUM(X4:X12) -> 0 | Y13: =SUM(Y4:Y12) -> 0 | AA13: =SUM(AA4:AA12) -> 0 | AB13: =SUM(AB4:AB12) -> 0 | AC13: =SUM(AC4:AC12) -> 0 | AE13: =SUM(AE4:AE12) -> 0 | AF13: =SUM(AF4:AF12) -> 0 | AG13: =SUM(AG4:AG12) -> 0 | AI13: =SUM(AI4:AI12) -> 0 | AJ13: =SUM(AJ4:AJ12) -> 0 | AK13: =SUM(AK4:AK12) -> 0 | AM13: =SUM(AM4:AM12) -> 0 | AN13: =SUM(AN4:AN12) -> 0 | AO13: =SUM(AO4:AO12) -> 0 | AQ13: =SUM(AQ4:AQ12) -> 0 | AR13: =SUM(AR4:AR12) -> 0 | AS13: =SUM(AS4:AS12) -> 0 | AU13: =SUM(AU4:AU12) -> 0 | AV13: =SUM(AV4:AV12) -> 0 | AW13: =SUM(AW4:AW12) -> 0

Sheet index
B1: =SUBTOTAL(3,B3:B41) -> 39
B2: HRD컨설턴트 | C2: 팀명 | D2: 비고 | G2: 기업등급 | H2: 기업규모 | I2: 고객구분 | J2: 사업유형 | K2: 26년 사업유형 | L2: 매출구분 | M2: LMS 상태 | N2: 신성장동력 상품명
B3: 박정규 | C3: 기업교육1팀 | G3: 01 1~1000대 | H3: 01 대기업 | I3: 01 수성 | J3: 1. 온라인 - 단과 | K3: 01. 이러닝 - 통합위탁 | L3: 01 확정 | M3: 01 자체 LMS | N3: 1. 휴넷CEO 멤버십 | Q3: 통합위탁 | R3: 01. 이러닝 - 통합위탁
B4: 이재성 | C4: 기업교육1팀 | G4: 02 1001~2000대 | H4: 02 중견기업 | I4: 02 윈백 | J4: 2. 온라인 - 법정 | K4: 02. 이러닝 - 단과 | L4: 02 가망 | M4: 02 경쟁사 LMS | N4: 2. 휴넷CEO Executive MBA | Q4: 단과 | R4: 02. 이러닝 - 단과
B5: 황동현 | C5: 기업교육1팀 | G5: 03 2001~3000대 | H5: 03 우선지원기업 | I5: 03 신규 | J5: 3. 온라인 - 마이크로러닝 | K5: 03. 이러닝 - 법정 | L5: 03 기회 | M5: 03 휴넷 LMS | N5: 3. 팀장 리더십 저니 | Q5: 법정 | R5: 03. 이러닝 - 법정
B6: 장지웅 | C6: 기업교육1팀 | G6: 04 3000대 이후 | H6: 04 해당없음 | I6: 04 연장 | J6: 4. 하이브리드러닝 - 플립형 | K6: 04. 이러닝 - 마이크로러닝 | L6: 04 실주 | N6: 4. AI칼리지 | Q6: 마이크로러닝 | R6: 04. 이러닝 - 마이크로러닝
B7: 이태원 | C7: 기업교육1팀 | G7: 05 공공 | J7: 5. 하이브리드러닝 - 러닝저니 | K7: 05. 이러닝 - 북러닝 | L7: 05 Drop | N7: 5. 터닝포인트 팀장리더십스쿨 | Q7: 북러닝 | R7: 05. 이러닝 - 북러닝
B8: 강건모 | C8: 기업교육1팀 | J8: 6. 하이브리드러닝 - 집합형 | K8: 06. 이러닝 - 정부지원사업 | L8: 06 사업취소 | N8: 6. 마이 리더십 플레이북 | R8: [사용안함]06. 이러닝 - 휴넷플렉스
B9: 조미희 | C9: 기업교육1팀 | J9: 7. 휴넷CEO - 휴넷CEO | K9: 07. 이러닝 - 컨텐츠 임대/판매 | L9: 07 2023년 매출 | N9: 7. 휴넷 CEO 포사이트 포럼 | Q9: 컨텐츠 임대/판매 | R9: 07. 이러닝 - 컨텐츠 임대/판매
B10: 김도엽 | C10: 기업교육1팀 | J10: 8. 리더스아카데미 - 리더스아카데미 | K10: 08. 하이브리드러닝 - 하이브리드형 러닝 | L10: 08 2024년 매출 | N10: 8. 휴넷 SMB 파트너스 | Q10: 하이브리드형 러닝 | R10: 08. 하이브리드러닝 - 하이브리드형 러닝
B11: 김신정 | C11: 기업교육1팀 | J11: 9. 직무칼리지 - 마케팅 | K11: 09. 하이브리드러닝 - 순수 오프라인 | L11: 09 2025년 매출 | Q11: 순수 오프라인 | R11: 09. 하이브리드러닝 - 순수 오프라인
B12: 서대원 | C12: 기업교육1팀 | J12: 10. 컨텐츠 - 컨텐츠 개발 | K12: 10. 하이브리드러닝 - 특강 | Q12: 휴넷CEO멤버십 | R12: 10. 구독 - 휴넷CEO멤버십
B13: 전보람 | C13: 기업교육1팀 | J13: 11. 컨텐츠 - 컨텐츠 임대/판매 | K13: 11. 구독 - 휴넷CEO멤버십 | Q13: 휴넷 리더십저니 | R13: 11. 구독 - 휴넷 리더십저니
B14: 최상근 | C14: 기업교육1팀 | J14: 12. 컨텐츠 - 컨설팅 | K14: 12. 구독 - 휴넷 리더십저니 | Q14: 커리업 저니 | R14: 12. 구독 - 커리업 저니
B15: 김묘정 | C15: 기업교육2팀 | J15: 13. 솔루션 - 표준형 LABS | K15: 13. 구독 - 휴넷FLEX | Q15: Wisdom spring | R15: 13. 구독 - Wisdom spring
B16: 서동윤 | C16: 기업교육2팀 | J16: 14. 솔루션 - 맞춤형 LABS | K16: 14. 구독 - 기타 | Q16: 컨텐츠 개발 | R16: 14. 컨텐츠 - 컨텐츠 개발
B17: 장윤오 | C17: 기업교육2팀 | J17: 15. 솔루션 - 러닝저니메이커 | K17: 15. 컨텐츠 - 컨텐츠 개발 | Q17: LABS | R17: 15. 솔루션 - LABS
B18: 황재연 | C18: 기업교육2팀 | J18: 16. 솔루션 - 챗봇 | K18: 16. 솔루션 - LABS | Q18: 러닝메이커 | R18: 16. 솔루션 - 러닝메이커
B19: 안혜연 | C19: 기업교육2팀 | J19: 17. 솔루션 - 디지털뱃지 | K19: 17. 솔루션 - 러닝메이커 | Q19: 기타 | R19: 17. 솔루션 - 기타
B20: 김나리 | C20: 기업교육2팀 | J20: 18. 솔루션 - 라이브클래스 | K20: 18. 솔루션 - 기타 | Q20: BPO | R20: 18. 운영 - BPO
B21: 이종혁 | C21: 기업교육2팀 | J21: 19. 솔루션 - 퀴즈앤 | K21: 19. 운영 - BPO | Q21: 운영매출 | R21: 19. 운영 - 운영매출
B22: 고예서 | C22: 기업교육2팀 | J22: 20. 솔루션 - AI교강사 | K22: 20. 운영 - 운영매출 | Q22: 독서통신(제휴) | R22: 20. 기타 - 독서통신(제휴)
B23: 박혜원 | C23: 기업교육2팀 | J23: 21. 솔루션 - 모두의코딩 | K23: 21. 운영 - 바이패스 | Q23: 독서통신(휴넷) | R23: 21. 기타 - 독서통신(휴넷)
... B27: 방인혜 | C27: 기업교육3팀 | J27: 25. 운영 - 대관 | K27: 25. HU(B2C) - HU(B2C) | Q27: 기타 | R27: 25. 기타 - 기타
B28: 송승희 | C28: 기업교육3팀 | J28: 26. 정부지원사업 - HRDFLEX | Q28: 정부지원사업 | R28: 26. 이러닝 - 정부지원사업
B29: 김지훈 | C29: 기업교육3팀 | J29: 27. 정부지원사업 - 국민내일배움카드 | Q29: HU(B2C) | R29: 27. HU(B2C) - HU(B2C)
B30: 이지송 | C30: 기업교육3팀 | J30: 28. 정부지원사업 - K-디지털기초역량 | Q30: 휴넷FLEX | R30: 28.구독 - 휴넷FLEX
B31: 송민지 | C31: 기업교육3팀 | J31: 29. 정부지원사업 - 평생교육바우처
B32: 김두희 | C32: 기업교육4팀 | J32: 30. 정부지원사업 - B2C_고용보험환급
B33: 이나래 | C33: 기업교육4팀 | J33: 31. B2C - 일반과정
B34: 최재희 | C34: 기업교육4팀 | J34: 32. 기타 - 독서통신
B35: 김성경 | C35: 기업교육4팀 | J35: 33. 기타 - 도서학습
B36: 하예진 | C36: 기업교육4팀 | J36: 34. 기타 - 전화외국어
B37: 최수진 | C37: 기업교육4팀 | J37: 35. 기타 - 북러닝
B38: 방유진 | C38: 기업교육4팀 | J38: 36. 기타 - 기타
B39: 유형석 | C39: FS팀
B40: 김지선 | C40: FS팀
B41: 황중목 | C41: FS팀
B42: 남만기 | C42: FS팀
B43: 공통 DB | C43: 공통 DB
...

Sheet 요약
A3: 행 레이블 | B3: 합계 : 1월 마감 | C3: 합계 : 2월 마감 | D3: 합계 : 3월 마감 | E3: 합계 : 4월 예상 | F3: 합계 : 5월 예상 | G3: 합계 : 6월 예상 | H3: 합계 : 7월 예상 | I3: 합계 : 8월 예상 | J3: 합계 : 9월 예상 | K3: 합계 : 10월 예상 | L3: 합계 : 11월 예상 | M3: 합계 : 12월 예상 | N3: 합계 : 26년 예상매출합계
A4: 01 확정 | B4: 84721500 | C4: 48295800 | D4: 79332700 | E4: 409414500 | F4: 54660000 | G4: 108067000 | H4: 51500000 | I4: 277390000 | J4: 71390000 | K4: 72295000 | L4: 164494280 | M4: 1090765500 | N4: 2512326280
A5: 02 가망 | B5: 0 | C5: 0 | E5: 8350000 | F5: 164092000 | G5: 67350000 | H5: 35030000 | I5: 71350000 | J5: 82350000 | K5: 81350000 | L5: 84950000 | M5: 321557756 | N5: 916379756
A6: 03 기회 | B6: 0 | C6: 0 | E6: 0 | F6: 546500000 | G6: 275000000 | H6: 150000000 | I6: 45600000 | J6: 32000000 | K6: 180000000 | L6: 178000000 | M6: 655520000 | N6: 2062620000
A7: 총합계 | B7: 84721500 | C7: 48295800 | D7: 79332700 | E7: 417764500 | F7: 765252000 | G7: 450417000 | H7: 236530000 | I7: 394340000 | J7: 185740000 | K7: 333645000 | L7: 427444280 | M7: 2067843256 | N7: 5491326036
A15: 합계 : 26년 예상매출합계 | B15: 열 레이블
A16: 행 레이블 | B16: 01 확정 | C16: 02 가망 | D16: 03 기회 | E16: 총합계
A17: 유형석 | B17: 532627500 | C17: 134750000 | D17: 498000000 | E17: 1165377500
A18: 최상근 | B18: 1264994000 | C18: 453387756 | D18: 460920000 | E18: 2179301756
A19: 이동호 | B19: 448455280 | C19: 161642000 | D19: 831700000 | E19: 1441797280
A20: 임성은 | B20: 265249500 | C20: 166600000 | D20: 272000000 | E20: 703849500
A21: 국문정 | B21: 1000000 | E21: 1000000
A22: 총합계 | B22: 2512326280 | C22: 916379756 | D22: 2062620000 | E22: 5491326036

Sheet 검증용
B1: 사업전략팀 용 시트 | G1: 팀 취합본 | K1: 개인작성
C2: 검증구간 | F2: 기업명 (HSM 기준) | G2: 26년 사업유형 | H2: 26년 확정/가망/기회 | J2: 기업명 (HSM 기준) | K2: 26년 사업유형 | L2: 26년 확정/가망/기회
F3: =SUBTOTAL(3,F5:F1000) -> 0 | G3: =SUBTOTAL(3,G5:G1000) -> 0 | H3: =SUBTOTAL(3,H5:H1000) -> 0 | J3: =SUBTOTAL(3,J5:J1000) -> 0 | K3: =SUBTOTAL(3,K5:K1000) -> 0 | L3: =SUBTOTAL(3,L5:L1000) -> 0
B5: =F5=J5 -> TRUE | C5: =G5=K5 -> TRUE | D5: =H5=L5 -> TRUE
B6: =F6=J6 -> TRUE | C6: =G6=K6 -> TRUE | D6: =H6=L6 -> TRUE
B7: =F7=J7 -> TRUE | C7: =G7=K7 -> TRUE | D7: =H7=L7 -> TRUE
B8: =F8=J8 -> TRUE | C8: =G8=K8 -> TRUE | D8: =H8=L8 -> TRUE
B9: =F9=J9 -> TRUE | C9: =G9=K9 -> TRUE | D9: =H9=L9 -> TRUE
B10: =F10=J10 -> TRUE | C10: =G10=K10 -> TRUE | D10: =H10=L10 -> TRUE
B11: =F11=J11 -> TRUE | C11: =G11=K11 -> TRUE | D11: =H11=L11 -> TRUE
B12: =F12=J12 -> TRUE | C12: =G12=K12 -> TRUE | D12: =H12=L12 -> TRUE
B13: =F13=J13 -> TRUE | C13: =G13=K13 -> TRUE | D13: =H13=L13 -> TRUE
B14: =F14=J14 -> TRUE | C14: =G14=K14 -> TRUE | D14: =H14=L14 -> TRUE
B15: =F15=J15 -> TRUE | C15: =G15=K15 -> TRUE | D15: =H15=L15 -> TRUE
B16: =F16=J16 -> TRUE | C16: =G16=K16 -> TRUE | D16: =H16=L16 -> TRUE
... B281: =F281=J281 -> TRUE | C281: =G281=K281 -> TRUE | D281: =H281=L281 -> TRUE
